Workbook

Sheet January
AQ1: January
B2: HABIT TRACKER | C2: Daily Progress | AA2: Weekly Progress | AI2: Goal | AK2: Overall Stats | AO2: MonthNo | AP2: =MATCH($B$9,$AQ$1:$AQ$12,0) -> 1 | AQ2: February
AI3: =SUMPRODUCT(--(LEN($B$17:$B$28)>0))*$AP$3 -> 310 | AK3: =IF(AI3=0,0,AI6/AI3) -> 0 | AO3: Days | AP3: =DAY(DATE($B$7,$AP$2+1,0)) -> 31 | AQ3: March
AQ4: April
B5: SETTINGS | AI5: Completed | AO5: Completed | AP5: =AI6 -> 0 | AQ5: May
B6: Year | AI6: =SUMPRODUCT(($B$17:$B$28<>"")*($C$17:$AG$28=TRUE())) -> 0 | AO6: Left | AP6: =AI9 -> 310 | AQ6: June
B7: 2026 | AQ7: July
B8: Month | AI8: Left | AO8: Week 1 | AP8: =IF(OR(COUNTIF(C$16:I$16,">0")=0,SUMPRODUCT(--(LEN($B$17:$B$28)>0))=0),0,SUMPRODUCT(($B$17:$B$28<>"")*(C$17:I$28=TRUE()))/(SUMPRODUCT(--(LEN($B$17:$B$28)>0))*COUNTIF(C$16:I$16,">0"))) -> 0 | AQ8: August
B9: January | AI9: =AI3-AI6 -> 310 | AO9: Week 2 | AP9: =IF(OR(COUNTIF(J$16:P$16,">0")=0,SUMPRODUCT(--(LEN($B$17:$B$28)>0))=0),0,SUMPRODUCT(($B$17:$B$28<>"")*(J$17:P$28=TRUE()))/(SUMPRODUCT(--(LEN($B$17:$B$28)>0))*COUNTIF(J$16:P$16,">0"))) -> 0 | AQ9: September
B10: How to use: tick the boxes each day; pick Mood (1-10) and Sleep (hrs) below the grid; rename habits in column B. Blue text = editable. | AO10: Week 3 | AP10: =IF(OR(COUNTIF(Q$16:W$16,">0")=0,SUMPRODUCT(--(LEN($B$17:$B$28)>0))=0),0,SUMPRODUCT(($B$17:$B$28<>"")*(Q$17:W$28=TRUE()))/(SUMPRODUCT(--(LEN($B$17:$B$28)>0))*COUNTIF(Q$16:W$16,">0"))) -> 0 | AQ10: October
AO11: Week 4 | AP11: =IF(OR(COUNTIF(X$16:AD$16,">0")=0,SUMPRODUCT(--(LEN($B$17:$B$28)>0))=0),0,SUMPRODUCT(($B$17:$B$28<>"")*(X$17:AD$28=TRUE()))/(SUMPRODUCT(--(LEN($B$17:$B$28)>0))*COUNTIF(X$16:AD$16,">0"))) -> 0 | AQ11: November
AO12: Week 5 | AP12: =IF(OR(COUNTIF(AE$16:AG$16,">0")=0,SUMPRODUCT(--(LEN($B$17:$B$28)>0))=0),0,SUMPRODUCT(($B$17:$B$28<>"")*(AE$17:AG$28=TRUE()))/(SUMPRODUCT(--(LEN($B$17:$B$28)>0))*COUNTIF(AE$16:AG$16,">0"))) -> 0 | AQ12: December
B14: My Habits | C14: Week 1 | J14: Week 2 | Q14: Week 3 | X14: Week 4 | AE14: Week 5 | AI14: Analysis
C15: =IF(1>$AP$3,"",CHOOSE(WEEKDAY(DATE($B$7,$AP$2,1)),"Su","Mo","Tu","We","Th","Fr","Sa")) -> Th | D15: =IF(2>$AP$3,"",CHOOSE(WEEKDAY(DATE($B$7,$AP$2,2)),"Su","Mo","Tu","We","Th","Fr","Sa")) -> Fr | E15: =IF(3>$AP$3,"",CHOOSE(WEEKDAY(DATE($B$7,$AP$2,3)),"Su","Mo","Tu","We","Th","Fr","Sa")) -> Sa | F15: =IF(4>$AP$3,"",CHOOSE(WEEKDAY(DATE($B$7,$AP$2,4)),"Su","Mo","Tu","We","Th","Fr","Sa")) -> Su | G15: =IF(5>$AP$3,"",CHOOSE(WEEKDAY(DATE($B$7,$AP$2,5)),"Su","Mo","Tu","We","Th","Fr","Sa")) -> Mo | H15: =IF(6>$AP$3,"",CHOOSE(WEEKDAY(DATE($B$7,$AP$2,6)),"Su","Mo","Tu","We","Th","Fr","Sa")) -> Tu | I15: =IF(7>$AP$3,"",CHOOSE(WEEKDAY(DATE($B$7,$AP$2,7)),"Su","Mo","Tu","We","Th","Fr","Sa")) -> We | J15: =IF(8>$AP$3,"",CHOOSE(WEEKDAY(DATE($B$7,$AP$2,8)),"Su","Mo","Tu","We","Th","Fr","Sa")) -> Th | K15: =IF(9>$AP$3,"",CHOOSE(WEEKDAY(DATE($B$7,$AP$2,9)),"Su","Mo","Tu","We","Th","Fr","Sa")) -> Fr | L15: =IF(10>$AP$3,"",CHOOSE(WEEKDAY(DATE($B$7,$AP$2,10)),"Su","Mo","Tu","We","Th","Fr","Sa")) -> Sa | M15: =IF(11>$AP$3,"",CHOOSE(WEEKDAY(DATE($B$7,$AP$2,11)),"Su","Mo","Tu","We","Th","Fr","Sa")) -> Su | N15: =IF(12>$AP$3,"",CHOOSE(WEEKDAY(DATE($B$7,$AP$2,12)),"Su","Mo","Tu","We","Th","Fr","Sa")) -> Mo | O15: =IF(13>$AP$3,"",CHOOSE(WEEKDAY(DATE($B$7,$AP$2,13)),"Su","Mo","Tu","We","Th","Fr","Sa")) -> Tu | P15: =IF(14>$AP$3,"",CHOOSE(WEEKDAY(DATE($B$7,$AP$2,14)),"Su","Mo","Tu","We","Th","Fr","Sa")) -> We | Q15: =IF(15>$AP$3,"",CHOOSE(WEEKDAY(DATE($B$7,$AP$2,15)),"Su","Mo","Tu","We","Th","Fr","Sa")) -> Th | R15: =IF(16>$AP$3,"",CHOOSE(WEEKDAY(DATE($B$7,$AP$2,16)),"Su","Mo","Tu","We","Th","Fr","Sa")) -> Fr | S15: =IF(17>$AP$3,"",CHOOSE(WEEKDAY(DATE($B$7,$AP$2,17)),"Su","Mo","Tu","We","Th","Fr","Sa")) -> Sa | T15: =IF(18>$AP$3,"",CHOOSE(WEEKDAY(DATE($B$7,$AP$2,18)),"Su","Mo","Tu","We","Th","Fr","Sa")) -> Su | U15: =IF(19>$AP$3,"",CHOOSE(WEEKDAY(DATE($B$7,$AP$2,19)),"Su","Mo","Tu","We","Th","Fr","Sa")) -> Mo | V15: =IF(20>$AP$3,"",CHOOSE(WEEKDAY(DATE($B$7,$AP$2,20)),"Su","Mo","Tu","We","Th","Fr","Sa")) -> Tu | W15: =IF(21>$AP$3,"",CHOOSE(WEEKDAY(DATE($B$7,$AP$2,21)),"Su","Mo","Tu","We","Th","Fr","Sa")) -> We | X15: =IF(22>$AP$3,"",CHOOSE(WEEKDAY(DATE($B$7,$AP$2,22)),"Su","Mo","Tu","We","Th","Fr","Sa")) -> Th | Y15: =IF(23>$AP$3,"",CHOOSE(WEEKDAY(DATE($B$7,$AP$2,23)),"Su","Mo","Tu","We","Th","Fr","Sa")) -> Fr | Z15: =IF(24>$AP$3,"",CHOOSE(WEEKDAY(DATE($B$7,$AP$2,24)),"Su","Mo","Tu","We","Th","Fr","Sa")) -> Sa | AA15: =IF(25>$AP$3,"",CHOOSE(WEEKDAY(DATE($B$7,$AP$2,25)),"Su","Mo","Tu","We","Th","Fr","Sa")) -> Su | AB15: =IF(26>$AP$3,"",CHOOSE(WEEKDAY(DATE($B$7,$AP$2,26)),"Su","Mo","Tu","We","Th","Fr","Sa")) -> Mo | AC15: =IF(27>$AP$3,"",CHOOSE(WEEKDAY(DATE($B$7,$AP$2,27)),"Su","Mo","Tu","We","Th","Fr","Sa")) -> Tu | AD15: =IF(28>$AP$3,"",CHOOSE(WEEKDAY(DATE($B$7,$AP$2,28)),"Su","Mo","Tu","We","Th","Fr","Sa")) -> We | AE15: =IF(29>$AP$3,"",CHOOSE(WEEKDAY(DATE($B$7,$AP$2,29)),"Su","Mo","Tu","We","Th","Fr","Sa")) -> Th | AF15: =IF(30>$AP$3,"",CHOOSE(WEEKDAY(DATE($B$7,$AP$2,30)),"Su","Mo","Tu","We","Th","Fr","Sa")) -> Fr | AG15: =IF(31>$AP$3,"",CHOOSE(WEEKDAY(DATE($B$7,$AP$2,31)),"Su","Mo","Tu","We","Th","Fr","Sa")) -> Sa
C16: =IF(1>$AP$3,"",1) -> 1 | D16: =IF(2>$AP$3,"",2) -> 2 | E16: =IF(3>$AP$3,"",3) -> 3 | F16: =IF(4>$AP$3,"",4) -> 4 | G16: =IF(5>$AP$3,"",5) -> 5 | H16: =IF(6>$AP$3,"",6) -> 6 | I16: =IF(7>$AP$3,"",7) -> 7 | J16: =IF(8>$AP$3,"",8) -> 8 | K16: =IF(9>$AP$3,"",9) -> 9 | L16: =IF(10>$AP$3,"",10) -> 10 | M16: =IF(11>$AP$3,"",11) -> 11 | N16: =IF(12>$AP$3,"",12) -> 12 | O16: =IF(13>$AP$3,"",13) -> 13 | P16: =IF(14>$AP$3,"",14) -> 14 | Q16: =IF(15>$AP$3,"",15) -> 15 | R16: =IF(16>$AP$3,"",16) -> 16 | S16: =IF(17>$AP$3,"",17) -> 17 | T16: =IF(18>$AP$3,"",18) -> 18 | U16: =IF(19>$AP$3,"",19) -> 19 | V16: =IF(20>$AP$3,"",20) -> 20 | W16: =IF(21>$AP$3,"",21) -> 21 | X16: =IF(22>$AP$3,"",22) -> 22 | Y16: =IF(23>$AP$3,"",23) -> 23 | Z16: =IF(24>$AP$3,"",24) -> 24 | AA16: =IF(25>$AP$3,"",25) -> 25 | AB16: =IF(26>$AP$3,"",26) -> 26 | AC16: =IF(27>$AP$3,"",27) -> 27 | AD16: =IF(28>$AP$3,"",28) -> 28 | AE16: =IF(29>$AP$3,"",29) -> 29 | AF16: =IF(30>$AP$3,"",30) -> 30 | AG16: =IF(31>$AP$3,"",31) -> 31 | AI16: Goal | AJ16: Actual | AK16: Left | AL16: Progress | AM16: %
B17: Wake up at 05:00 ⏰ | C17: =FALSE() -> FALSE | D17: =FALSE() -> FALSE | E17: =FALSE() -> FALSE | F17: =FALSE() -> FALSE | G17: =FALSE() -> FALSE | H17: =FALSE() -> FALSE | I17: =FALSE() -> FALSE | J17: =FALSE() -> FALSE | ... AG17: =FALSE() -> FALSE | AI17: =IF($B17="","",$AP$3) -> 31 | AJ17: =IF($B17="","",COUNTIF(C17:AG17,TRUE())) -> 0 | AK17: =IF($B17="","",AI17-AJ17) -> 31 | AL17: =IF($B17="","",AJ17/AI17) -> 0 | AM17: =IF($B17="","",AJ17/AI17) -> 0 | AN17: =IF($B17="",-1,AM17-ROW()/100000) -> -0.00017
B18: Stretching 🧘 | C18: =FALSE() -> FALSE | D18: =FALSE() -> FALSE | E18: =FALSE() -> FALSE | F18: =FALSE() -> FALSE | G18: =FALSE() -> FALSE | H18: =FALSE() -> FALSE | I18: =FALSE() -> FALSE | J18: =FALSE() -> FALSE | ... AG18: =FALSE() -> FALSE | AI18: =IF($B18="","",$AP$3) -> 31 | AJ18: =IF($B18="","",COUNTIF(C18:AG18,TRUE())) -> 0 | AK18: =IF($B18="","",AI18-AJ18) -> 31 | AL18: =IF($B18="","",AJ18/AI18) -> 0 | AM18: =IF($B18="","",AJ18/AI18) -> 0 | AN18: =IF($B18="",-1,AM18-ROW()/100000) -> -0.00018
B19: Gym 💪 | C19: =FALSE() -> FALSE | D19: =FALSE() -> FALSE | E19: =FALSE() -> FALSE | F19: =FALSE() -> FALSE | G19: =FALSE() -> FALSE | H19: =FALSE() -> FALSE | I19: =FALSE() -> FALSE | J19: =FALSE() -> FALSE | ... AG19: =FALSE() -> FALSE | AI19: =IF($B19="","",$AP$3) -> 31 | AJ19: =IF($B19="","",COUNTIF(C19:AG19,TRUE())) -> 0 | AK19: =IF($B19="","",AI19-AJ19) -> 31 | AL19: =IF($B19="","",AJ19/AI19) -> 0 | AM19: =IF($B19="","",AJ19/AI19) -> 0 | AN19: =IF($B19="",-1,AM19-ROW()/100000) -> -0.00019
B20: Reading / Learning 📖 | C20: =FALSE() -> FALSE | D20: =FALSE() -> FALSE | E20: =FALSE() -> FALSE | F20: =FALSE() -> FALSE | G20: =FALSE() -> FALSE | H20: =FALSE() -> FALSE | I20: =FALSE() -> FALSE | J20: =FALSE() -> FALSE | ... AG20: =FALSE() -> FALSE | AI20: =IF($B20="","",$AP$3) -> 31 | AJ20: =IF($B20="","",COUNTIF(C20:AG20,TRUE())) -> 0 | AK20: =IF($B20="","",AI20-AJ20) -> 31 | AL20: =IF($B20="","",AJ20/AI20) -> 0 | AM20: =IF($B20="","",AJ20/AI20) -> 0 | AN20: =IF($B20="",-1,AM20-ROW()/100000) -> -0.0002
B21: Day Planning 📅 | C21: =FALSE() -> FALSE | D21: =FALSE() -> FALSE | E21: =FALSE() -> FALSE | F21: =FALSE() -> FALSE | G21: =FALSE() -> FALSE | H21: =FALSE() -> FALSE | I21: =FALSE() -> FALSE | J21: =FALSE() -> FALSE | ... AG21: =FALSE() -> FALSE | AI21: =IF($B21="","",$AP$3) -> 31 | AJ21: =IF($B21="","",COUNTIF(C21:AG21,TRUE())) -> 0 | AK21: =IF($B21="","",AI21-AJ21) -> 31 | AL21: =IF($B21="","",AJ21/AI21) -> 0 | AM21: =IF($B21="","",AJ21/AI21) -> 0 | AN21: =IF($B21="",-1,AM21-ROW()/100000) -> -0.00021
B22: Project Work 🎯 | C22: =FALSE() -> FALSE | D22: =FALSE() -> FALSE | E22: =FALSE() -> FALSE | F22: =FALSE() -> FALSE | G22: =FALSE() -> FALSE | H22: =FALSE() -> FALSE | I22: =FALSE() -> FALSE | J22: =FALSE() -> FALSE | ... AG22: =FALSE() -> FALSE | AI22: =IF($B22="","",$AP$3) -> 31 | AJ22: =IF($B22="","",COUNTIF(C22:AG22,TRUE())) -> 0 | AK22: =IF($B22="","",AI22-AJ22) -> 31 | AL22: =IF($B22="","",AJ22/AI22) -> 0 | AM22: =IF($B22="","",AJ22/AI22) -> 0 | AN22: =IF($B22="",-1,AM22-ROW()/100000) -> -0.00022
B23: No Alcohol 🚫 | C23: =FALSE() -> FALSE | D23: =FALSE() -> FALSE | E23: =FALSE() -> FALSE | F23: =FALSE() -> FALSE | G23: =FALSE() -> FALSE | H23: =FALSE() -> FALSE | I23: =FALSE() -> FALSE | J23: =FALSE() -> FALSE | ... AG23: =FALSE() -> FALSE | AI23: =IF($B23="","",$AP$3) -> 31 | AJ23: =IF($B23="","",COUNTIF(C23:AG23,TRUE())) -> 0 | AK23: =IF($B23="","",AI23-AJ23) -> 31 | AL23: =IF($B23="","",AJ23/AI23) -> 0 | AM23: =IF($B23="","",AJ23/AI23) -> 0 | AN23: =IF($B23="",-1,AM23-ROW()/100000) -> -0.00023
B24: Social Media Detox 🌿 | C24: =FALSE() -> FALSE | D24: =FALSE() -> FALSE | E24: =FALSE() -> FALSE | F24: =FALSE() -> FALSE | G24: =FALSE() -> FALSE | H24: =FALSE() -> FALSE | I24: =FALSE() -> FALSE | J24: =FALSE() -> FALSE | ... AG24: =FALSE() -> FALSE | AI24: =IF($B24="","",$AP$3) -> 31 | AJ24: =IF($B24="","",COUNTIF(C24:AG24,TRUE())) -> 0 | AK24: =IF($B24="","",AI24-AJ24) -> 31 | AL24: =IF($B24="","",AJ24/AI24) -> 0 | AM24: =IF($B24="","",AJ24/AI24) -> 0 | AN24: =IF($B24="",-1,AM24-ROW()/100000) -> -0.00024
B25: Goal Journaling 📒 | C25: =FALSE() -> FALSE | D25: =FALSE() -> FALSE | E25: =FALSE() -> FALSE | F25: =FALSE() -> FALSE | G25: =FALSE() -> FALSE | H25: =FALSE() -> FALSE | I25: =FALSE() -> FALSE | J25: =FALSE() -> FALSE | ... AG25: =FALSE() -> FALSE | AI25: =IF($B25="","",$AP$3) -> 31 | AJ25: =IF($B25="","",COUNTIF(C25:AG25,TRUE())) -> 0 | AK25: =IF($B25="","",AI25-AJ25) -> 31 | AL25: =IF($B25="","",AJ25/AI25) -> 0 | AM25: =IF($B25="","",AJ25/AI25) -> 0 | AN25: =IF($B25="",-1,AM25-ROW()/100000) -> -0.00025
B26: Cold Shower 🚿 | C26: =FALSE() -> FALSE | D26: =FALSE() -> FALSE | E26: =FALSE() -> FALSE | F26: =FALSE() -> FALSE | G26: =FALSE() -> FALSE | H26: =FALSE() -> FALSE | I26: =FALSE() -> FALSE | J26: =FALSE() -> FALSE | ... AG26: =FALSE() -> FALSE | AI26: =IF($B26="","",$AP$3) -> 31 | AJ26: =IF($B26="","",COUNTIF(C26:AG26,TRUE())) -> 0 | AK26: =IF($B26="","",AI26-AJ26) -> 31 | AL26: =IF($B26="","",AJ26/AI26) -> 0 | AM26: =IF($B26="","",AJ26/AI26) -> 0 | AN26: =IF($B26="",-1,AM26-ROW()/100000) -> -0.00026
C27: =FALSE() -> FALSE | D27: =FALSE() -> FALSE | E27: =FALSE() -> FALSE | F27: =FALSE() -> FALSE | G27: =FALSE() -> FALSE | H27: =FALSE() -> FALSE | I27: =FALSE() -> FALSE | J27: =FALSE() -> FALSE | ... AG27: =FALSE() -> FALSE | AI27: =IF($B27="","",$AP$3) | AJ27: =IF($B27="","",COUNTIF(C27:AG27,TRUE())) | AK27: =IF($B27="","",AI27-AJ27) | AL27: =IF($B27="","",AJ27/AI27) | AM27: =IF($B27="","",AJ27/AI27) | AN27: =IF($B27="",-1,AM27-ROW()/100000) -> -1
C28: =FALSE() -> FALSE | D28: =FALSE() -> FALSE | E28: =FALSE() -> FALSE | F28: =FALSE() -> FALSE | G28: =FALSE() -> FALSE | H28: =FALSE() -> FALSE | I28: =FALSE() -> FALSE | J28: =FALSE() -> FALSE | ... AG28: =FALSE() -> FALSE | AI28: =IF($B28="","",$AP$3) | AJ28: =IF($B28="","",COUNTIF(C28:AG28,TRUE())) | AK28: =IF($B28="","",AI28-AJ28) | AL28: =IF($B28="","",AJ28/AI28) | AM28: =IF($B28="","",AJ28/AI28) | AN28: =IF($B28="",-1,AM28-ROW()/100000) -> -1
B29: Daily % | C29: =IF(OR(C$16="",SUMPRODUCT(--(LEN($B$17:$B$28)>0))=0),"",SUMPRODUCT(($B$17:$B$28<>"")*(C$17:C$28=TRUE()))/SUMPRODUCT(--(LEN($B$17:$B$28)>0))) -> 0 | D29: =IF(OR(D$16="",SUMPRODUCT(--(LEN($B$17:$B$28)>0))=0),"",SUMPRODUCT(($B$17:$B$28<>"")*(D$17:D$28=TRUE()))/SUMPRODUCT(--(LEN($B$17:$B$28)>0))) -> 0 | E29: =IF(OR(E$16="",SUMPRODUCT(--(LEN($B$17:$B$28)>0))=0),"",SUMPRODUCT(($B$17:$B$28<>"")*(E$17:E$28=TRUE()))/SUMPRODUCT(--(LEN($B$17:$B$28)>0))) -> 0 | F29: =IF(OR(F$16="",SUMPRODUCT(--(LEN($B$17:$B$28)>0))=0),"",SUMPRODUCT(($B$17:$B$28<>"")*(F$17:F$28=TRUE()))/SUMPRODUCT(--(LEN($B$17:$B$28)>0))) -> 0 | G29: =IF(OR(G$16="",SUMPRODUCT(--(LEN($B$17:$B$28)>0))=0),"",SUMPRODUCT(($B$17:$B$28<>"")*(G$17:G$28=TRUE()))/SUMPRODUCT(--(LEN($B$17:$B$28)>0))) -> 0 | H29: =IF(OR(H$16="",SUMPRODUCT(--(LEN($B$17:$B$28)>0))=0),"",SUMPRODUCT(($B$17:$B$28<>"")*(H$17:H$28=TRUE()))/SUMPRODUCT(--(LEN($B$17:$B$28)>0))) -> 0 | I29: =IF(OR(I$16="",SUMPRODUCT(--(LEN($B$17:$B$28)>0))=0),"",SUMPRODUCT(($B$17:$B$28<>"")*(I$17:I$28=TRUE()))/SUMPRODUCT(--(LEN($B$17:$B$28)>0))) -> 0 | J29: =IF(OR(J$16="",SUMPRODUCT(--(LEN($B$17:$B$28)>0))=0),"",SUMPRODUCT(($B$17:$B$28<>"")*(J$17:J$28=TRUE()))/SUMPRODUCT(--(LEN($B$17:$B$28)>0))) -> 0 | ... AG29: =IF(OR(AG$16="",SUMPRODUCT(--(LEN($B$17:$B$28)>0))=0),"",SUMPRODUCT(($B$17:$B$28<>"")*(AG$17:AG$28=TRUE()))/SUMPRODUCT(--(LEN($B$17:$B$28)>0))) -> 0
C31: Overall Wellness | AI31: TOP 10 HABITS
B32: Mood (1-10) | AI32: 1 | AJ32: =IF(LARGE($AN$17:$AN$28,1)<0,"",INDEX($B$17:$B$28,MATCH(LARGE($AN$17:$AN$28,1),$AN$17:$AN$28,0))) | AM32: =IF(AJ32="","",INDEX($AM$17:$AM$28,MATCH(LARGE($AN$17:$AN$28,1),$AN$17:$AN$28,0)))
B33: Hours of Sleep | AI33: 2 | AJ33: =IF(LARGE($AN$17:$AN$28,2)<0,"",INDEX($B$17:$B$28,MATCH(LARGE($AN$17:$AN$28,2),$AN$17:$AN$28,0))) | AM33: =IF(AJ33="","",INDEX($AM$17:$AM$28,MATCH(LARGE($AN$17:$AN$28,2),$AN$17:$AN$28,0)))
AI34: 3 | AJ34: =IF(LARGE($AN$17:$AN$28,3)<0,"",INDEX($B$17:$B$28,MATCH(LARGE($AN$17:$AN$28,3),$AN$17:$AN$28,0))) | AM34: =IF(AJ34="","",INDEX($AM$17:$AM$28,MATCH(LARGE($AN$17:$AN$28,3),$AN$17:$AN$28,0)))
AI35: 4 | AJ35: =IF(LARGE($AN$17:$AN$28,4)<0,"",INDEX($B$17:$B$28,MATCH(LARGE($AN$17:$AN$28,4),$AN$17:$AN$28,0))) | AM35: =IF(AJ35="","",INDEX($AM$17:$AM$28,MATCH(LARGE($AN$17:$AN$28,4),$AN$17:$AN$28,0)))
AI36: 5 | AJ36: =IF(LARGE($AN$17:$AN$28,5)<0,"",INDEX($B$17:$B$28,MATCH(LARGE($AN$17:$AN$28,5),$AN$17:$AN$28,0))) | AM36: =IF(AJ36="","",INDEX($AM$17:$AM$28,MATCH(LARGE($AN$17:$AN$28,5),$AN$17:$AN$28,0)))
AI37: 6 | AJ37: =IF(LARGE($AN$17:$AN$28,6)<0,"",INDEX($B$17:$B$28,MATCH(LARGE($AN$17:$AN$28,6),$AN$17:$AN$28,0))) | AM37: =IF(AJ37="","",INDEX($AM$17:$AM$28,MATCH(LARGE($AN$17:$AN$28,6),$AN$17:$AN$28,0)))
AI38: 7 | AJ38: =IF(LARGE($AN$17:$AN$28,7)<0,"",INDEX($B$17:$B$28,MATCH(LARGE($AN$17:$AN$28,7),$AN$17:$AN$28,0))) | AM38: =IF(AJ38="","",INDEX($AM$17:$AM$28,MATCH(LARGE($AN$17:$AN$28,7),$AN$17:$AN$28,0)))
AI39: 8 | AJ39: =IF(LARGE($AN$17:$AN$28,8)<0,"",INDEX($B$17:$B$28,MATCH(LARGE($AN$17:$AN$28,8),$AN$17:$AN$28,0))) | AM39: =IF(AJ39="","",INDEX($AM$17:$AM$28,MATCH(LARGE($AN$17:$AN$28,8),$AN$17:$AN$28,0)))
AI40: 9 | AJ40: =IF(LARGE($AN$17:$AN$28,9)<0,"",INDEX($B$17:$B$28,MATCH(LARGE($AN$17:$AN$28,9),$AN$17:$AN$28,0))) | AM40: =IF(AJ40="","",INDEX($AM$17:$AM$28,MATCH(LARGE($AN$17:$AN$28,9),$AN$17:$AN$28,0)))
AI41: 10 | AJ41: =IF(LARGE($AN$17:$AN$28,10)<0,"",INDEX($B$17:$B$28,MATCH(LARGE($AN$17:$AN$28,10),$AN$17:$AN$28,0))) | AM41: =IF(AJ41="","",INDEX($AM$17:$AM$28,MATCH(LARGE($AN$17:$AN$28,10),$AN$17:$AN$28,0)))
C48: =IF(C$16="","",C$15) -> Th | D48: =IF(D$16="","",D$15) -> Fr | E48: =IF(E$16="","",E$15) -> Sa | F48: =IF(F$16="","",F$15) -> Su | G48: =IF(G$16="","",G$15) -> Mo | H48: =IF(H$16="","",H$15) -> Tu | I48: =IF(I$16="","",I$15) -> We | J48: =IF(J$16="","",J$15) -> Th | ... AG48: =IF(AG$16="","",AG$15) -> Sa

Sheet February
AQ1: January
B2: HABIT TRACKER | C2: Daily Progress | AA2: Weekly Progress | AI2: Goal | AK2: Overall Stats | AO2: MonthNo | AP2: =MATCH($B$9,$AQ$1:$AQ$12,0) -> 2 | AQ2: February
AI3: =SUMPRODUCT(--(LEN($B$17:$B$28)>0))*$AP$3 -> 280 | AK3: =IF(AI3=0,0,AI6/AI3) -> 0 | AO3: Days | AP3: =DAY(DATE($B$7,$AP$2+1,0)) -> 28 | AQ3: March
AQ4: April
B5: SETTINGS | AI5: Completed | AO5: Completed | AP5: =AI6 -> 0 | AQ5: May
B6: Year | AI6: =SUMPRODUCT(($B$17:$B$28<>"")*($C$17:$AG$28=TRUE())) -> 0 | AO6: Left | AP6: =AI9 -> 280 | AQ6: June
B7: =January!$B$7 -> 2026 | AQ7: July
B8: Month | AI8: Left | AO8: Week 1 | AP8: =IF(OR(COUNTIF(C$16:I$16,">0")=0,SUMPRODUCT(--(LEN($B$17:$B$28)>0))=0),0,SUMPRODUCT(($B$17:$B$28<>"")*(C$17:I$28=TRUE()))/(SUMPRODUCT(--(LEN($B$17:$B$28)>0))*COUNTIF(C$16:I$16,">0"))) -> 0 | AQ8: August
B9: February | AI9: =AI3-AI6 -> 280 | AO9: Week 2 | AP9: =IF(OR(COUNTIF(J$16:P$16,">0")=0,SUMPRODUCT(--(LEN($B$17:$B$28)>0))=0),0,SUMPRODUCT(($B$17:$B$28<>"")*(J$17:P$28=TRUE()))/(SUMPRODUCT(--(LEN($B$17:$B$28)>0))*COUNTIF(J$16:P$16,">0"))) -> 0 | AQ9: September
B10: How to use: tick the boxes each day; pick Mood (1-10) and Sleep (hrs) below the grid; rename habits in column B. Blue text = editable. | AO10: Week 3 | AP10: =IF(OR(COUNTIF(Q$16:W$16,">0")=0,SUMPRODUCT(--(LEN($B$17:$B$28)>0))=0),0,SUMPRODUCT(($B$17:$B$28<>"")*(Q$17:W$28=TRUE()))/(SUMPRODUCT(--(LEN($B$17:$B$28)>0))*COUNTIF(Q$16:W$16,">0"))) -> 0 | AQ10: October
AO11: Week 4 | AP11: =IF(OR(COUNTIF(X$16:AD$16,">0")=0,SUMPRODUCT(--(LEN($B$17:$B$28)>0))=0),0,SUMPRODUCT(($B$17:$B$28<>"")*(X$17:AD$28=TRUE()))/(SUMPRODUCT(--(LEN($B$17:$B$28)>0))*COUNTIF(X$16:AD$16,">0"))) -> 0 | AQ11: November
AO12: Week 5 | AP12: =IF(OR(COUNTIF(AE$16:AG$16,">0")=0,SUMPRODUCT(--(LEN($B$17:$B$28)>0))=0),0,SUMPRODUCT(($B$17:$B$28<>"")*(AE$17:AG$28=TRUE()))/(SUMPRODUCT(--(LEN($B$17:$B$28)>0))*COUNTIF(AE$16:AG$16,">0"))) -> 0 | AQ12: December
B14: My Habits | C14: Week 1 | J14: Week 2 | Q14: Week 3 | X14: Week 4 | AE14: Week 5 | AI14: Analysis
C15: =IF(1>$AP$3,"",CHOOSE(WEEKDAY(DATE($B$7,$AP$2,1)),"Su","Mo","Tu","We","Th","Fr","Sa")) -> Su | D15: =IF(2>$AP$3,"",CHOOSE(WEEKDAY(DATE($B$7,$AP$2,2)),"Su","Mo","Tu","We","Th","Fr","Sa")) -> Mo | E15: =IF(3>$AP$3,"",CHOOSE(WEEKDAY(DATE($B$7,$AP$2,3)),"Su","Mo","Tu","We","Th","Fr","Sa")) -> Tu | F15: =IF(4>$AP$3,"",CHOOSE(WEEKDAY(DATE($B$7,$AP$2,4)),"Su","Mo","Tu","We","Th","Fr","Sa")) -> We | G15: =IF(5>$AP$3,"",CHOOSE(WEEKDAY(DATE($B$7,$AP$2,5)),"Su","Mo","Tu","We","Th","Fr","Sa")) -> Th | H15: =IF(6>$AP$3,"",CHOOSE(WEEKDAY(DATE($B$7,$AP$2,6)),"Su","Mo","Tu","We","Th","Fr","Sa")) -> Fr | I15: =IF(7>$AP$3,"",CHOOSE(WEEKDAY(DATE($B$7,$AP$2,7)),"Su","Mo","Tu","We","Th","Fr","Sa")) -> Sa | J15: =IF(8>$AP$3,"",CHOOSE(WEEKDAY(DATE($B$7,$AP$2,8)),"Su","Mo","Tu","We","Th","Fr","Sa")) -> Su | K15: =IF(9>$AP$3,"",CHOOSE(WEEKDAY(DATE($B$7,$AP$2,9)),"Su","Mo","Tu","We","Th","Fr","Sa")) -> Mo | L15: =IF(10>$AP$3,"",CHOOSE(WEEKDAY(DATE($B$7,$AP$2,10)),"Su","Mo","Tu","We","Th","Fr","Sa")) -> Tu | M15: =IF(11>$AP$3,"",CHOOSE(WEEKDAY(DATE($B$7,$AP$2,11)),"Su","Mo","Tu","We","Th","Fr","Sa")) -> We | N15: =IF(12>$AP$3,"",CHOOSE(WEEKDAY(DATE($B$7,$AP$2,12)),"Su","Mo","Tu","We","Th","Fr","Sa")) -> Th | O15: =IF(13>$AP$3,"",CHOOSE(WEEKDAY(DATE($B$7,$AP$2,13)),"Su","Mo","Tu","We","Th","Fr","Sa")) -> Fr | P15: =IF(14>$AP$3,"",CHOOSE(WEEKDAY(DATE($B$7,$AP$2,14)),"Su","Mo","Tu","We","Th","Fr","Sa")) -> Sa | Q15: =IF(15>$AP$3,"",CHOOSE(WEEKDAY(DATE($B$7,$AP$2,15)),"Su","Mo","Tu","We","Th","Fr","Sa")) -> Su | R15: =IF(16>$AP$3,"",CHOOSE(WEEKDAY(DATE($B$7,$AP$2,16)),"Su","Mo","Tu","We","Th","Fr","Sa")) -> Mo | S15: =IF(17>$AP$3,"",CHOOSE(WEEKDAY(DATE($B$7,$AP$2,17)),"Su","Mo","Tu","We","Th","Fr","Sa")) -> Tu | T15: =IF(18>$AP$3,"",CHOOSE(WEEKDAY(DATE($B$7,$AP$2,18)),"Su","Mo","Tu","We","Th","Fr","Sa")) -> We | U15: =IF(19>$AP$3,"",CHOOSE(WEEKDAY(DATE($B$7,$AP$2,19)),"Su","Mo","Tu","We","Th","Fr","Sa")) -> Th | V15: =IF(20>$AP$3,"",CHOOSE(WEEKDAY(DATE($B$7,$AP$2,20)),"Su","Mo","Tu","We","Th","Fr","Sa")) -> Fr | W15: =IF(21>$AP$3,"",CHOOSE(WEEKDAY(DATE($B$7,$AP$2,21)),"Su","Mo","Tu","We","Th","Fr","Sa")) -> Sa | X15: =IF(22>$AP$3,"",CHOOSE(WEEKDAY(DATE($B$7,$AP$2,22)),"Su","Mo","Tu","We","Th","Fr","Sa")) -> Su | Y15: =IF(23>$AP$3,"",CHOOSE(WEEKDAY(DATE($B$7,$AP$2,23)),"Su","Mo","Tu","We","Th","Fr","Sa")) -> Mo | Z15: =IF(24>$AP$3,"",CHOOSE(WEEKDAY(DATE($B$7,$AP$2,24)),"Su","Mo","Tu","We","Th","Fr","Sa")) -> Tu | AA15: =IF(25>$AP$3,"",CHOOSE(WEEKDAY(DATE($B$7,$AP$2,25)),"Su","Mo","Tu","We","Th","Fr","Sa")) -> We | AB15: =IF(26>$AP$3,"",CHOOSE(WEEKDAY(DATE($B$7,$AP$2,26)),"Su","Mo","Tu","We","Th","Fr","Sa")) -> Th | AC15: =IF(27>$AP$3,"",CHOOSE(WEEKDAY(DATE($B$7,$AP$2,27)),"Su","Mo","Tu","We","Th","Fr","Sa")) -> Fr | AD15: =IF(28>$AP$3,"",CHOOSE(WEEKDAY(DATE($B$7,$AP$2,28)),"Su","Mo","Tu","We","Th","Fr","Sa")) -> Sa | AE15: =IF(29>$AP$3,"",CHOOSE(WEEKDAY(DATE($B$7,$AP$2,29)),"Su","Mo","Tu","We","Th","Fr","Sa")) | AF15: =IF(30>$AP$3,"",CHOOSE(WEEKDAY(DATE($B$7,$AP$2,30)),"Su","Mo","Tu","We","Th","Fr","Sa")) | AG15: =IF(31>$AP$3,"",CHOOSE(WEEKDAY(DATE($B$7,$AP$2,31)),"Su","Mo","Tu","We","Th","Fr","Sa"))
C16: =IF(1>$AP$3,"",1) -> 1 | D16: =IF(2>$AP$3,"",2) -> 2 | E16: =IF(3>$AP$3,"",3) -> 3 | F16: =IF(4>$AP$3,"",4) -> 4 | G16: =IF(5>$AP$3,"",5) -> 5 | H16: =IF(6>$AP$3,"",6) -> 6 | I16: =IF(7>$AP$3,"",7) -> 7 | J16: =IF(8>$AP$3,"",8) -> 8 | K16: =IF(9>$AP$3,"",9) -> 9 | L16: =IF(10>$AP$3,"",10) -> 10 | M16: =IF(11>$AP$3,"",11) -> 11 | N16: =IF(12>$AP$3,"",12) -> 12 | O16: =IF(13>$AP$3,"",13) -> 13 | P16: =IF(14>$AP$3,"",14) -> 14 | Q16: =IF(15>$AP$3,"",15) -> 15 | R16: =IF(16>$AP$3,"",16) -> 16 | S16: =IF(17>$AP$3,"",17) -> 17 | T16: =IF(18>$AP$3,"",18) -> 18 | U16: =IF(19>$AP$3,"",19) -> 19 | V16: =IF(20>$AP$3,"",20) -> 20 | W16: =IF(21>$AP$3,"",21) -> 21 | X16: =IF(22>$AP$3,"",22) -> 22 | Y16: =IF(23>$AP$3,"",23) -> 23 | Z16: =IF(24>$AP$3,"",24) -> 24 | AA16: =IF(25>$AP$3,"",25) -> 25 | AB16: =IF(26>$AP$3,"",26) -> 26 | AC16: =IF(27>$AP$3,"",27) -> 27 | AD16: =IF(28>$AP$3,"",28) -> 28 | AE16: =IF(29>$AP$3,"",29) | AF16: =IF(30>$AP$3,"",30) | AG16: =IF(31>$AP$3,"",31) | AI16: Goal | AJ16: Actual | AK16: Left | AL16: Progress | AM16: %
B17: Wake up at 05:00 ⏰ | C17: =FALSE() -> FALSE | D17: =FALSE() -> FALSE | E17: =FALSE() -> FALSE | F17: =FALSE() -> FALSE | G17: =FALSE() -> FALSE | H17: =FALSE() -> FALSE | I17: =FALSE() -> FALSE | J17: =FALSE() -> FALSE | ... AG17: =FALSE() -> FALSE | AI17: =IF($B17="","",$AP$3) -> 28 | AJ17: =IF($B17="","",COUNTIF(C17:AG17,TRUE())) -> 0 | AK17: =IF($B17="","",AI17-AJ17) -> 28 | AL17: =IF($B17="","",AJ17/AI17) -> 0 | AM17: =IF($B17="","",AJ17/AI17) -> 0 | AN17: =IF($B17="",-1,AM17-ROW()/100000) -> -0.00017
B18: Stretching 🧘 | C18: =FALSE() -> FALSE | D18: =FALSE() -> FALSE | E18: =FALSE() -> FALSE | F18: =FALSE() -> FALSE | G18: =FALSE() -> FALSE | H18: =FALSE() -> FALSE | I18: =FALSE() -> FALSE | J18: =FALSE() -> FALSE | ... AG18: =FALSE() -> FALSE | AI18: =IF($B18="","",$AP$3) -> 28 | AJ18: =IF($B18="","",COUNTIF(C18:AG18,TRUE())) -> 0 | AK18: =IF($B18="","",AI18-AJ18) -> 28 | AL18: =IF($B18="","",AJ18/AI18) -> 0 | AM18: =IF($B18="","",AJ18/AI18) -> 0 | AN18: =IF($B18="",-1,AM18-ROW()/100000) -> -0.00018
B19: Gym 💪 | C19: =FALSE() -> FALSE | D19: =FALSE() -> FALSE | E19: =FALSE() -> FALSE | F19: =FALSE() -> FALSE | G19: =FALSE() -> FALSE | H19: =FALSE() -> FALSE | I19: =FALSE() -> FALSE | J19: =FALSE() -> FALSE | ... AG19: =FALSE() -> FALSE | AI19: =IF($B19="","",$AP$3) -> 28 | AJ19: =IF($B19="","",COUNTIF(C19:AG19,TRUE())) -> 0 | AK19: =IF($B19="","",AI19-AJ19) -> 28 | AL19: =IF($B19="","",AJ19/AI19) -> 0 | AM19: =IF($B19="","",AJ19/AI19) -> 0 | AN19: =IF($B19="",-1,AM19-ROW()/100000) -> -0.00019
B20: Reading / Learning 📖 | C20: =FALSE() -> FALSE | D20: =FALSE() -> FALSE | E20: =FALSE() -> FALSE | F20: =FALSE() -> FALSE | G20: =FALSE() -> FALSE | H20: =FALSE() -> FALSE | I20: =FALSE() -> FALSE | J20: =FALSE() -> FALSE | ... AG20: =FALSE() -> FALSE | AI20: =IF($B20="","",$AP$3) -> 28 | AJ20: =IF($B20="","",COUNTIF(C20:AG20,TRUE())) -> 0 | AK20: =IF($B20="","",AI20-AJ20) -> 28 | AL20: =IF($B20="","",AJ20/AI20) -> 0 | AM20: =IF($B20="","",AJ20/AI20) -> 0 | AN20: =IF($B20="",-1,AM20-ROW()/100000) -> -0.0002
B21: Day Planning 📅 | C21: =FALSE() -> FALSE | D21: =FALSE() -> FALSE | E21: =FALSE() -> FALSE | F21: =FALSE() -> FALSE | G21: =FALSE() -> FALSE | H21: =FALSE() -> FALSE | I21: =FALSE() -> FALSE | J21: =FALSE() -> FALSE | ... AG21: =FALSE() -> FALSE | AI21: =IF($B21="","",$AP$3) -> 28 | AJ21: =IF($B21="","",COUNTIF(C21:AG21,TRUE())) -> 0 | AK21: =IF($B21="","",AI21-AJ21) -> 28 | AL21: =IF($B21="","",AJ21/AI21) -> 0 | AM21: =IF($B21="","",AJ21/AI21) -> 0 | AN21: =IF($B21="",-1,AM21-ROW()/100000) -> -0.00021
B22: Project Work 🎯 | C22: =FALSE() -> FALSE | D22: =FALSE() -> FALSE | E22: =FALSE() -> FALSE | F22: =FALSE() -> FALSE | G22: =FALSE() -> FALSE | H22: =FALSE() -> FALSE | I22: =FALSE() -> FALSE | J22: =FALSE() -> FALSE | ... AG22: =FALSE() -> FALSE | AI22: =IF($B22="","",$AP$3) -> 28 | AJ22: =IF($B22="","",COUNTIF(C22:AG22,TRUE())) -> 0 | AK22: =IF($B22="","",AI22-AJ22) -> 28 | AL22: =IF($B22="","",AJ22/AI22) -> 0 | AM22: =IF($B22="","",AJ22/AI22) -> 0 | AN22: =IF($B22="",-1,AM22-ROW()/100000) -> -0.00022
B23: No Alcohol 🚫 | C23: =FALSE() -> FALSE | D23: =FALSE() -> FALSE | E23: =FALSE() -> FALSE | F23: =FALSE() -> FALSE | G23: =FALSE() -> FALSE | H23: =FALSE() -> FALSE | I23: =FALSE() -> FALSE | J23: =FALSE() -> FALSE | ... AG23: =FALSE() -> FALSE | AI23: =IF($B23="","",$AP$3) -> 28 | AJ23: =IF($B23="","",COUNTIF(C23:AG23,TRUE())) -> 0 | AK23: =IF($B23="","",AI23-AJ23) -> 28 | AL23: =IF($B23="","",AJ23/AI23) -> 0 | AM23: =IF($B23="","",AJ23/AI23) -> 0 | AN23: =IF($B23="",-1,AM23-ROW()/100000) -> -0.00023
B24: Social Media Detox 🌿 | C24: =FALSE() -> FALSE | D24: =FALSE() -> FALSE | E24: =FALSE() -> FALSE | F24: =FALSE() -> FALSE | G24: =FALSE() -> FALSE | H24: =FALSE() -> FALSE | I24: =FALSE() -> FALSE | J24: =FALSE() -> FALSE | ... AG24: =FALSE() -> FALSE | AI24: =IF($B24="","",$AP$3) -> 28 | AJ24: =IF($B24="","",COUNTIF(C24:AG24,TRUE())) -> 0 | AK24: =IF($B24="","",AI24-AJ24) -> 28 | AL24: =IF($B24="","",AJ24/AI24) -> 0 | AM24: =IF($B24="","",AJ24/AI24) -> 0 | AN24: =IF($B24="",-1,AM24-ROW()/100000) -> -0.00024
B25: Goal Journaling 📒 | C25: =FALSE() -> FALSE | D25: =FALSE() -> FALSE | E25: =FALSE() -> FALSE | F25: =FALSE() -> FALSE | G25: =FALSE() -> FALSE | H25: =FALSE() -> FALSE | I25: =FALSE() -> FALSE | J25: =FALSE() -> FALSE | ... AG25: =FALSE() -> FALSE | AI25: =IF($B25="","",$AP$3) -> 28 | AJ25: =IF($B25="","",COUNTIF(C25:AG25,TRUE())) -> 0 | AK25: =IF($B25="","",AI25-AJ25) -> 28 | AL25: =IF($B25="","",AJ25/AI25) -> 0 | AM25: =IF($B25="","",AJ25/AI25) -> 0 | AN25: =IF($B25="",-1,AM25-ROW()/100000) -> -0.00025
B26: Cold Shower 🚿 | C26: =FALSE() -> FALSE | D26: =FALSE() -> FALSE | E26: =FALSE() -> FALSE | F26: =FALSE() -> FALSE | G26: =FALSE() -> FALSE | H26: =FALSE() -> FALSE | I26: =FALSE() -> FALSE | J26: =FALSE() -> FALSE | ... AG26: =FALSE() -> FALSE | AI26: =IF($B26="","",$AP$3) -> 28 | AJ26: =IF($B26="","",COUNTIF(C26:AG26,TRUE())) -> 0 | AK26: =IF($B26="","",AI26-AJ26) -> 28 | AL26: =IF($B26="","",AJ26/AI26) -> 0 | AM26: =IF($B26="","",AJ26/AI26) -> 0 | AN26: =IF($B26="",-1,AM26-ROW()/100000) -> -0.00026
C27: =FALSE() -> FALSE | D27: =FALSE() -> FALSE | E27: =FALSE() -> FALSE | F27: =FALSE() -> FALSE | G27: =FALSE() -> FALSE | H27: =FALSE() -> FALSE | I27: =FALSE() -> FALSE | J27: =FALSE() -> FALSE | ... AG27: =FALSE() -> FALSE | AI27: =IF($B27="","",$AP$3) | AJ27: =IF($B27="","",COUNTIF(C27:AG27,TRUE())) | AK27: =IF($B27="","",AI27-AJ27) | AL27: =IF($B27="","",AJ27/AI27) | AM27: =IF($B27="","",AJ27/AI27) | AN27: =IF($B27="",-1,AM27-ROW()/100000) -> -1
C28: =FALSE() -> FALSE | D28: =FALSE() -> FALSE | E28: =FALSE() -> FALSE | F28: =FALSE() -> FALSE | G28: =FALSE() -> FALSE | H28: =FALSE() -> FALSE | I28: =FALSE() -> FALSE | J28: =FALSE() -> FALSE | ... AG28: =FALSE() -> FALSE | AI28: =IF($B28="","",$AP$3) | AJ28: =IF($B28="","",COUNTIF(C28:AG28,TRUE())) | AK28: =IF($B28="","",AI28-AJ28) | AL28: =IF($B28="","",AJ28/AI28) | AM28: =IF($B28="","",AJ28/AI28) | AN28: =IF($B28="",-1,AM28-ROW()/100000) -> -1
B29: Daily % | C29: =IF(OR(C$16="",SUMPRODUCT(--(LEN($B$17:$B$28)>0))=0),"",SUMPRODUCT(($B$17:$B$28<>"")*(C$17:C$28=TRUE()))/SUMPRODUCT(--(LEN($B$17:$B$28)>0))) -> 0 | D29: =IF(OR(D$16="",SUMPRODUCT(--(LEN($B$17:$B$28)>0))=0),"",SUMPRODUCT(($B$17:$B$28<>"")*(D$17:D$28=TRUE()))/SUMPRODUCT(--(LEN($B$17:$B$28)>0))) -> 0 | E29: =IF(OR(E$16="",SUMPRODUCT(--(LEN($B$17:$B$28)>0))=0),"",SUMPRODUCT(($B$17:$B$28<>"")*(E$17:E$28=TRUE()))/SUMPRODUCT(--(LEN($B$17:$B$28)>0))) -> 0 | F29: =IF(OR(F$16="",SUMPRODUCT(--(LEN($B$17:$B$28)>0))=0),"",SUMPRODUCT(($B$17:$B$28<>"")*(F$17:F$28=TRUE()))/SUMPRODUCT(--(LEN($B$17:$B$28)>0))) -> 0 | G29: =IF(OR(G$16="",SUMPRODUCT(--(LEN($B$17:$B$28)>0))=0),"",SUMPRODUCT(($B$17:$B$28<>"")*(G$17:G$28=TRUE()))/SUMPRODUCT(--(LEN($B$17:$B$28)>0))) -> 0 | H29: =IF(OR(H$16="",SUMPRODUCT(--(LEN($B$17:$B$28)>0))=0),"",SUMPRODUCT(($B$17:$B$28<>"")*(H$17:H$28=TRUE()))/SUMPRODUCT(--(LEN($B$17:$B$28)>0))) -> 0 | I29: =IF(OR(I$16="",SUMPRODUCT(--(LEN($B$17:$B$28)>0))=0),"",SUMPRODUCT(($B$17:$B$28<>"")*(I$17:I$28=TRUE()))/SUMPRODUCT(--(LEN($B$17:$B$28)>0))) -> 0 | J29: =IF(OR(J$16="",SUMPRODUCT(--(LEN($B$17:$B$28)>0))=0),"",SUMPRODUCT(($B$17:$B$28<>"")*(J$17:J$28=TRUE()))/SUMPRODUCT(--(LEN($B$17:$B$28)>0))) -> 0 | ... AG29: =IF(OR(AG$16="",SUMPRODUCT(--(LEN($B$17:$B$28)>0))=0),"",SUMPRODUCT(($B$17:$B$28<>"")*(AG$17:AG$28=TRUE()))/SUMPRODUCT(--(LEN($B$17:$B$28)>0)))
C31: Overall Wellness | AI31: TOP 10 HABITS
B32: Mood (1-10) | AI32: 1 | AJ32: =IF(LARGE($AN$17:$AN$28,1)<0,"",INDEX($B$17:$B$28,MATCH(LARGE($AN$17:$AN$28,1),$AN$17:$AN$28,0))) | AM32: =IF(AJ32="","",INDEX($AM$17:$AM$28,MATCH(LARGE($AN$17:$AN$28,1),$AN$17:$AN$28,0)))
B33: Hours of Sleep | AI33: 2 | AJ33: =IF(LARGE($AN$17:$AN$28,2)<0,"",INDEX($B$17:$B$28,MATCH(LARGE($AN$17:$AN$28,2),$AN$17:$AN$28,0))) | AM33: =IF(AJ33="","",INDEX($AM$17:$AM$28,MATCH(LARGE($AN$17:$AN$28,2),$AN$17:$AN$28,0)))
AI34: 3 | AJ34: =IF(LARGE($AN$17:$AN$28,3)<0,"",INDEX($B$17:$B$28,MATCH(LARGE($AN$17:$AN$28,3),$AN$17:$AN$28,0))) | AM34: =IF(AJ34="","",INDEX($AM$17:$AM$28,MATCH(LARGE($AN$17:$AN$28,3),$AN$17:$AN$28,0)))
AI35: 4 | AJ35: =IF(LARGE($AN$17:$AN$28,4)<0,"",INDEX($B$17:$B$28,MATCH(LARGE($AN$17:$AN$28,4),$AN$17:$AN$28,0))) | AM35: =IF(AJ35="","",INDEX($AM$17:$AM$28,MATCH(LARGE($AN$17:$AN$28,4),$AN$17:$AN$28,0)))
AI36: 5 | AJ36: =IF(LARGE($AN$17:$AN$28,5)<0,"",INDEX($B$17:$B$28,MATCH(LARGE($AN$17:$AN$28,5),$AN$17:$AN$28,0))) | AM36: =IF(AJ36="","",INDEX($AM$17:$AM$28,MATCH(LARGE($AN$17:$AN$28,5),$AN$17:$AN$28,0)))
AI37: 6 | AJ37: =IF(LARGE($AN$17:$AN$28,6)<0,"",INDEX($B$17:$B$28,MATCH(LARGE($AN$17:$AN$28,6),$AN$17:$AN$28,0))) | AM37: =IF(AJ37="","",INDEX($AM$17:$AM$28,MATCH(LARGE($AN$17:$AN$28,6),$AN$17:$AN$28,0)))
AI38: 7 | AJ38: =IF(LARGE($AN$17:$AN$28,7)<0,"",INDEX($B$17:$B$28,MATCH(LARGE($AN$17:$AN$28,7),$AN$17:$AN$28,0))) | AM38: =IF(AJ38="","",INDEX($AM$17:$AM$28,MATCH(LARGE($AN$17:$AN$28,7),$AN$17:$AN$28,0)))
AI39: 8 | AJ39: =IF(LARGE($AN$17:$AN$28,8)<0,"",INDEX($B$17:$B$28,MATCH(LARGE($AN$17:$AN$28,8),$AN$17:$AN$28,0))) | AM39: =IF(AJ39="","",INDEX($AM$17:$AM$28,MATCH(LARGE($AN$17:$AN$28,8),$AN$17:$AN$28,0)))
AI40: 9 | AJ40: =IF(LARGE($AN$17:$AN$28,9)<0,"",INDEX($B$17:$B$28,MATCH(LARGE($AN$17:$AN$28,9),$AN$17:$AN$28,0))) | AM40: =IF(AJ40="","",INDEX($AM$17:$AM$28,MATCH(LARGE($AN$17:$AN$28,9),$AN$17:$AN$28,0)))
AI41: 10 | AJ41: =IF(LARGE($AN$17:$AN$28,10)<0,"",INDEX($B$17:$B$28,MATCH(LARGE($AN$17:$AN$28,10),$AN$17:$AN$28,0))) | AM41: =IF(AJ41="","",INDEX($AM$17:$AM$28,MATCH(LARGE($AN$17:$AN$28,10),$AN$17:$AN$28,0)))
C48: =IF(C$16="","",C$15) -> Su | D48: =IF(D$16="","",D$15) -> Mo | E48: =IF(E$16="","",E$15) -> Tu | F48: =IF(F$16="","",F$15) -> We | G48: =IF(G$16="","",G$15) -> Th | H48: =IF(H$16="","",H$15) -> Fr | I48: =IF(I$16="","",I$15) -> Sa | J48: =IF(J$16="","",J$15) -> Su | ... AG48: =IF(AG$16="","",AG$15)

Sheet March
AQ1: January
B2: HABIT TRACKER | C2: Daily Progress | AA2: Weekly Progress | AI2: Goal | AK2: Overall Stats | AO2: MonthNo | AP2: =MATCH($B$9,$AQ$1:$AQ$12,0) -> 3 | AQ2: February
AI3: =SUMPRODUCT(--(LEN($B$17:$B$28)>0))*$AP$3 -> 310 | AK3: =IF(AI3=0,0,AI6/AI3) -> 0 | AO3: Days | AP3: =DAY(DATE($B$7,$AP$2+1,0)) -> 31 | AQ3: March
AQ4: April
B5: SETTINGS | AI5: Completed | AO5: Completed | AP5: =AI6 -> 0 | AQ5: May
B6: Year | AI6: =SUMPRODUCT(($B$17:$B$28<>"")*($C$17:$AG$28=TRUE())) -> 0 | AO6: Left | AP6: =AI9 -> 310 | AQ6: June
B7: =January!$B$7 -> 2026 | AQ7: July
B8: Month | AI8: Left | AO8: Week 1 | AP8: =IF(OR(COUNTIF(C$16:I$16,">0")=0,SUMPRODUCT(--(LEN($B$17:$B$28)>0))=0),0,SUMPRODUCT(($B$17:$B$28<>"")*(C$17:I$28=TRUE()))/(SUMPRODUCT(--(LEN($B$17:$B$28)>0))*COUNTIF(C$16:I$16,">0"))) -> 0 | AQ8: August
B9: March | AI9: =AI3-AI6 -> 310 | AO9: Week 2 | AP9: =IF(OR(COUNTIF(J$16:P$16,">0")=0,SUMPRODUCT(--(LEN($B$17:$B$28)>0))=0),0,SUMPRODUCT(($B$17:$B$28<>"")*(J$17:P$28=TRUE()))/(SUMPRODUCT(--(LEN($B$17:$B$28)>0))*COUNTIF(J$16:P$16,">0"))) -> 0 | AQ9: September
B10: How to use: tick the boxes each day; pick Mood (1-10) and Sleep (hrs) below the grid; rename habits in column B. Blue text = editable. | AO10: Week 3 | AP10: =IF(OR(COUNTIF(Q$16:W$16,">0")=0,SUMPRODUCT(--(LEN($B$17:$B$28)>0))=0),0,SUMPRODUCT(($B$17:$B$28<>"")*(Q$17:W$28=TRUE()))/(SUMPRODUCT(--(LEN($B$17:$B$28)>0))*COUNTIF(Q$16:W$16,">0"))) -> 0 | AQ10: October
AO11: Week 4 | AP11: =IF(OR(COUNTIF(X$16:AD$16,">0")=0,SUMPRODUCT(--(LEN($B$17:$B$28)>0))=0),0,SUMPRODUCT(($B$17:$B$28<>"")*(X$17:AD$28=TRUE()))/(SUMPRODUCT(--(LEN($B$17:$B$28)>0))*COUNTIF(X$16:AD$16,">0"))) -> 0 | AQ11: November
AO12: Week 5 | AP12: =IF(OR(COUNTIF(AE$16:AG$16,">0")=0,SUMPRODUCT(--(LEN($B$17:$B$28)>0))=0),0,SUMPRODUCT(($B$17:$B$28<>"")*(AE$17:AG$28=TRUE()))/(SUMPRODUCT(--(LEN($B$17:$B$28)>0))*COUNTIF(AE$16:AG$16,">0"))) -> 0 | AQ12: December
B14: My Habits | C14: Week 1 | J14: Week 2 | Q14: Week 3 | X14: Week 4 | AE14: Week 5 | AI14: Analysis
C15: =IF(1>$AP$3,"",CHOOSE(WEEKDAY(DATE($B$7,$AP$2,1)),"Su","Mo","Tu","We","Th","Fr","Sa")) -> Su | D15: =IF(2>$AP$3,"",CHOOSE(WEEKDAY(DATE($B$7,$AP$2,2)),"Su","Mo","Tu","We","Th","Fr","Sa")) -> Mo | E15: =IF(3>$AP$3,"",CHOOSE(WEEKDAY(DATE($B$7,$AP$2,3)),"Su","Mo","Tu","We","Th","Fr","Sa")) -> Tu | F15: =IF(4>$AP$3,"",CHOOSE(WEEKDAY(DATE($B$7,$AP$2,4)),"Su","Mo","Tu","We","Th","Fr","Sa")) -> We | G15: =IF(5>$AP$3,"",CHOOSE(WEEKDAY(DATE($B$7,$AP$2,5)),"Su","Mo","Tu","We","Th","Fr","Sa")) -> Th | H15: =IF(6>$AP$3,"",CHOOSE(WEEKDAY(DATE($B$7,$AP$2,6)),"Su","Mo","Tu","We","Th","Fr","Sa")) -> Fr | I15: =IF(7>$AP$3,"",CHOOSE(WEEKDAY(DATE($B$7,$AP$2,7)),"Su","Mo","Tu","We","Th","Fr","Sa")) -> Sa | J15: =IF(8>$AP$3,"",CHOOSE(WEEKDAY(DATE($B$7,$AP$2,8)),"Su","Mo","Tu","We","Th","Fr","Sa")) -> Su | K15: =IF(9>$AP$3,"",CHOOSE(WEEKDAY(DATE($B$7,$AP$2,9)),"Su","Mo","Tu","We","Th","Fr","Sa")) -> Mo | L15: =IF(10>$AP$3,"",CHOOSE(WEEKDAY(DATE($B$7,$AP$2,10)),"Su","Mo","Tu","We","Th","Fr","Sa")) -> Tu | M15: =IF(11>$AP$3,"",CHOOSE(WEEKDAY(DATE($B$7,$AP$2,11)),"Su","Mo","Tu","We","Th","Fr","Sa")) -> We | N15: =IF(12>$AP$3,"",CHOOSE(WEEKDAY(DATE($B$7,$AP$2,12)),"Su","Mo","Tu","We","Th","Fr","Sa")) -> Th | O15: =IF(13>$AP$3,"",CHOOSE(WEEKDAY(DATE($B$7,$AP$2,13)),"Su","Mo","Tu","We","Th","Fr","Sa")) -> Fr | P15: =IF(14>$AP$3,"",CHOOSE(WEEKDAY(DATE($B$7,$AP$2,14)),"Su","Mo","Tu","We","Th","Fr","Sa")) -> Sa | Q15: =IF(15>$AP$3,"",CHOOSE(WEEKDAY(DATE($B$7,$AP$2,15)),"Su","Mo","Tu","We","Th","Fr","Sa")) -> Su | R15: =IF(16>$AP$3,"",CHOOSE(WEEKDAY(DATE($B$7,$AP$2,16)),"Su","Mo","Tu","We","Th","Fr","Sa")) -> Mo | S15: =IF(17>$AP$3,"",CHOOSE(WEEKDAY(DATE($B$7,$AP$2,17)),"Su","Mo","Tu","We","Th","Fr","Sa")) -> Tu | T15: =IF(18>$AP$3,"",CHOOSE(WEEKDAY(DATE($B$7,$AP$2,18)),"Su","Mo","Tu","We","Th","Fr","Sa")) -> We | U15: =IF(19>$AP$3,"",CHOOSE(WEEKDAY(DATE($B$7,$AP$2,19)),"Su","Mo","Tu","We","Th","Fr","Sa")) -> Th | V15: =IF(20>$AP$3,"",CHOOSE(WEEKDAY(DATE($B$7,$AP$2,20)),"Su","Mo","Tu","We","Th","Fr","Sa")) -> Fr | W15: =IF(21>$AP$3,"",CHOOSE(WEEKDAY(DATE($B$7,$AP$2,21)),"Su","Mo","Tu","We","Th","Fr","Sa")) -> Sa | X15: =IF(22>$AP$3,"",CHOOSE(WEEKDAY(DATE($B$7,$AP$2,22)),"Su","Mo","Tu","We","Th","Fr","Sa")) -> Su | Y15: =IF(23>$AP$3,"",CHOOSE(WEEKDAY(DATE($B$7,$AP$2,23)),"Su","Mo","Tu","We","Th","Fr","Sa")) -> Mo | Z15: =IF(24>$AP$3,"",CHOOSE(WEEKDAY(DATE($B$7,$AP$2,24)),"Su","Mo","Tu","We","Th","Fr","Sa")) -> Tu | AA15: =IF(25>$AP$3,"",CHOOSE(WEEKDAY(DATE($B$7,$AP$2,25)),"Su","Mo","Tu","We","Th","Fr","Sa")) -> We | AB15: =IF(26>$AP$3,"",CHOOSE(WEEKDAY(DATE($B$7,$AP$2,26)),"Su","Mo","Tu","We","Th","Fr","Sa")) -> Th | AC15: =IF(27>$AP$3,"",CHOOSE(WEEKDAY(DATE($B$7,$AP$2,27)),"Su","Mo","Tu","We","Th","Fr","Sa")) -> Fr | AD15: =IF(28>$AP$3,"",CHOOSE(WEEKDAY(DATE($B$7,$AP$2,28)),"Su","Mo","Tu","We","Th","Fr","Sa")) -> Sa | AE15: =IF(29>$AP$3,"",CHOOSE(WEEKDAY(DATE($B$7,$AP$2,29)),"Su","Mo","Tu","We","Th","Fr","Sa")) -> Su | AF15: =IF(30>$AP$3,"",CHOOSE(WEEKDAY(DATE($B$7,$AP$2,30)),"Su","Mo","Tu","We","Th","Fr","Sa")) -> Mo | AG15: =IF(31>$AP$3,"",CHOOSE(WEEKDAY(DATE($B$7,$AP$2,31)),"Su","Mo","Tu","We","Th","Fr","Sa")) -> Tu
C16: =IF(1>$AP$3,"",1) -> 1 | D16: =IF(2>$AP$3,"",2) -> 2 | E16: =IF(3>$AP$3,"",3) -> 3 | F16: =IF(4>$AP$3,"",4) -> 4 | G16: =IF(5>$AP$3,"",5) -> 5 | H16: =IF(6>$AP$3,"",6) -> 6 | I16: =IF(7>$AP$3,"",7) -> 7 | J16: =IF(8>$AP$3,"",8) -> 8 | K16: =IF(9>$AP$3,"",9) -> 9 | L16: =IF(10>$AP$3,"",10) -> 10 | M16: =IF(11>$AP$3,"",11) -> 11 | N16: =IF(12>$AP$3,"",12) -> 12 | O16: =IF(13>$AP$3,"",13) -> 13 | P16: =IF(14>$AP$3,"",14) -> 14 | Q16: =IF(15>$AP$3,"",15) -> 15 | R16: =IF(16>$AP$3,"",16) -> 16 | S16: =IF(17>$AP$3,"",17) -> 17 | T16: =IF(18>$AP$3,"",18) -> 18 | U16: =IF(19>$AP$3,"",19) -> 19 | V16: =IF(20>$AP$3,"",20) -> 20 | W16: =IF(21>$AP$3,"",21) -> 21 | X16: =IF(22>$AP$3,"",22) -> 22 | Y16: =IF(23>$AP$3,"",23) -> 23 | Z16: =IF(24>$AP$3,"",24) -> 24 | AA16: =IF(25>$AP$3,"",25) -> 25 | AB16: =IF(26>$AP$3,"",26) -> 26 | AC16: =IF(27>$AP$3,"",27) -> 27 | AD16: =IF(28>$AP$3,"",28) -> 28 | AE16: =IF(29>$AP$3,"",29) -> 29 | AF16: =IF(30>$AP$3,"",30) -> 30 | AG16: =IF(31>$AP$3,"",31) -> 31 | AI16: Goal | AJ16: Actual | AK16: Left | AL16: Progress | AM16: %
B17: Wake up at 05:00 ⏰ | C17: =FALSE() -> FALSE | D17: =FALSE() -> FALSE | E17: =FALSE() -> FALSE | F17: =FALSE() -> FALSE | G17: =FALSE() -> FALSE | H17: =FALSE() -> FALSE | I17: =FALSE() -> FALSE | J17: =FALSE() -> FALSE | ... AG17: =FALSE() -> FALSE | AI17: =IF($B17="","",$AP$3) -> 31 | AJ17: =IF($B17="","",COUNTIF(C17:AG17,TRUE())) -> 0 | AK17: =IF($B17="","",AI17-AJ17) -> 31 | AL17: =IF($B17="","",AJ17/AI17) -> 0 | AM17: =IF($B17="","",AJ17/AI17) -> 0 | AN17: =IF($B17="",-1,AM17-ROW()/100000) -> -0.00017
B18: Stretching 🧘 | C18: =FALSE() -> FALSE | D18: =FALSE() -> FALSE | E18: =FALSE() -> FALSE | F18: =FALSE() -> FALSE | G18: =FALSE() -> FALSE | H18: =FALSE() -> FALSE | I18: =FALSE() -> FALSE | J18: =FALSE() -> FALSE | ... AG18: =FALSE() -> FALSE | AI18: =IF($B18="","",$AP$3) -> 31 | AJ18: =IF($B18="","",COUNTIF(C18:AG18,TRUE())) -> 0 | AK18: =IF($B18="","",AI18-AJ18) -> 31 | AL18: =IF($B18="","",AJ18/AI18) -> 0 | AM18: =IF($B18="","",AJ18/AI18) -> 0 | AN18: =IF($B18="",-1,AM18-ROW()/100000) -> -0.00018
B19: Gym 💪 | C19: =FALSE() -> FALSE | D19: =FALSE() -> FALSE | E19: =FALSE() -> FALSE | F19: =FALSE() -> FALSE | G19: =FALSE() -> FALSE | H19: =FALSE() -> FALSE | I19: =FALSE() -> FALSE | J19: =FALSE() -> FALSE | ... AG19: =FALSE() -> FALSE | AI19: =IF($B19="","",$AP$3) -> 31 | AJ19: =IF($B19="","",COUNTIF(C19:AG19,TRUE())) -> 0 | AK19: =IF($B19="","",AI19-AJ19) -> 31 | AL19: =IF($B19="","",AJ19/AI19) -> 0 | AM19: =IF($B19="","",AJ19/AI19) -> 0 | AN19: =IF($B19="",-1,AM19-ROW()/100000) -> -0.00019
B20: Reading / Learning 📖 | C20: =FALSE() -> FALSE | D20: =FALSE() -> FALSE | E20: =FALSE() -> FALSE | F20: =FALSE() -> FALSE | G20: =FALSE() -> FALSE | H20: =FALSE() -> FALSE | I20: =FALSE() -> FALSE | J20: =FALSE() -> FALSE | ... AG20: =FALSE() -> FALSE | AI20: =IF($B20="","",$AP$3) -> 31 | AJ20: =IF($B20="","",COUNTIF(C20:AG20,TRUE())) -> 0 | AK20: =IF($B20="","",AI20-AJ20) -> 31 | AL20: =IF($B20="","",AJ20/AI20) -> 0 | AM20: =IF($B20="","",AJ20/AI20) -> 0 | AN20: =IF($B20="",-1,AM20-ROW()/100000) -> -0.0002
B21: Day Planning 📅 | C21: =FALSE() -> FALSE | D21: =FALSE() -> FALSE | E21: =FALSE() -> FALSE | F21: =FALSE() -> FALSE | G21: =FALSE() -> FALSE | H21: =FALSE() -> FALSE | I21: =FALSE() -> FALSE | J21: =FALSE() -> FALSE | ... AG21: =FALSE() -> FALSE | AI21: =IF($B21="","",$AP$3) -> 31 | AJ21: =IF($B21="","",COUNTIF(C21:AG21,TRUE())) -> 0 | AK21: =IF($B21="","",AI21-AJ21) -> 31 | AL21: =IF($B21="","",AJ21/AI21) -> 0 | AM21: =IF($B21="","",AJ21/AI21) -> 0 | AN21: =IF($B21="",-1,AM21-ROW()/100000) -> -0.00021
B22: Project Work 🎯 | C22: =FALSE() -> FALSE | D22: =FALSE() -> FALSE | E22: =FALSE() -> FALSE | F22: =FALSE() -> FALSE | G22: =FALSE() -> FALSE | H22: =FALSE() -> FALSE | I22: =FALSE() -> FALSE | J22: =FALSE() -> FALSE | ... AG22: =FALSE() -> FALSE | AI22: =IF($B22="","",$AP$3) -> 31 | AJ22: =IF($B22="","",COUNTIF(C22:AG22,TRUE())) -> 0 | AK22: =IF($B22="","",AI22-AJ22) -> 31 | AL22: =IF($B22="","",AJ22/AI22) -> 0 | AM22: =IF($B22="","",AJ22/AI22) -> 0 | AN22: =IF($B22="",-1,AM22-ROW()/100000) -> -0.00022
B23: No Alcohol 🚫 | C23: =FALSE() -> FALSE | D23: =FALSE() -> FALSE | E23: =FALSE() -> FALSE | F23: =FALSE() -> FALSE | G23: =FALSE() -> FALSE | H23: =FALSE() -> FALSE | I23: =FALSE() -> FALSE | J23: =FALSE() -> FALSE | ... AG23: =FALSE() -> FALSE | AI23: =IF($B23="","",$AP$3) -> 31 | AJ23: =IF($B23="","",COUNTIF(C23:AG23,TRUE())) -> 0 | AK23: =IF($B23="","",AI23-AJ23) -> 31 | AL23: =IF($B23="","",AJ23/AI23) -> 0 | AM23: =IF($B23="","",AJ23/AI23) -> 0 | AN23: =IF($B23="",-1,AM23-ROW()/100000) -> -0.00023
B24: Social Media Detox 🌿 | C24: =FALSE() -> FALSE | D24: =FALSE() -> FALSE | E24: =FALSE() -> FALSE | F24: =FALSE() -> FALSE | G24: =FALSE() -> FALSE | H24: =FALSE() -> FALSE | I24: =FALSE() -> FALSE | J24: =FALSE() -> FALSE | ... AG24: =FALSE() -> FALSE | AI24: =IF($B24="","",$AP$3) -> 31 | AJ24: =IF($B24="","",COUNTIF(C24:AG24,TRUE())) -> 0 | AK24: =IF($B24="","",AI24-AJ24) -> 31 | AL24: =IF($B24="","",AJ24/AI24) -> 0 | AM24: =IF($B24="","",AJ24/AI24) -> 0 | AN24: =IF($B24="",-1,AM24-ROW()/100000) -> -0.00024
B25: Goal Journaling 📒 | C25: =FALSE() -> FALSE | D25: =FALSE() -> FALSE | E25: =FALSE() -> FALSE | F25: =FALSE() -> FALSE | G25: =FALSE() -> FALSE | H25: =FALSE() -> FALSE | I25: =FALSE() -> FALSE | J25: =FALSE() -> FALSE | ... AG25: =FALSE() -> FALSE | AI25: =IF($B25="","",$AP$3) -> 31 | AJ25: =IF($B25="","",COUNTIF(C25:AG25,TRUE())) -> 0 | AK25: =IF($B25="","",AI25-AJ25) -> 31 | AL25: =IF($B25="","",AJ25/AI25) -> 0 | AM25: =IF($B25="","",AJ25/AI25) -> 0 | AN25: =IF($B25="",-1,AM25-ROW()/100000) -> -0.00025
B26: Cold Shower 🚿 | C26: =FALSE() -> FALSE | D26: =FALSE() -> FALSE | E26: =FALSE() -> FALSE | F26: =FALSE() -> FALSE | G26: =FALSE() -> FALSE | H26: =FALSE() -> FALSE | I26: =FALSE() -> FALSE | J26: =FALSE() -> FALSE | ... AG26: =FALSE() -> FALSE | AI26: =IF($B26="","",$AP$3) -> 31 | AJ26: =IF($B26="","",COUNTIF(C26:AG26,TRUE())) -> 0 | AK26: =IF($B26="","",AI26-AJ26) -> 31 | AL26: =IF($B26="","",AJ26/AI26) -> 0 | AM26: =IF($B26="","",AJ26/AI26) -> 0 | AN26: =IF($B26="",-1,AM26-ROW()/100000) -> -0.00026
C27: =FALSE() -> FALSE | D27: =FALSE() -> FALSE | E27: =FALSE() -> FALSE | F27: =FALSE() -> FALSE | G27: =FALSE() -> FALSE | H27: =FALSE() -> FALSE | I27: =FALSE() -> FALSE | J27: =FALSE() -> FALSE | ... AG27: =FALSE() -> FALSE | AI27: =IF($B27="","",$AP$3) | AJ27: =IF($B27="","",COUNTIF(C27:AG27,TRUE())) | AK27: =IF($B27="","",AI27-AJ27) | AL27: =IF($B27="","",AJ27/AI27) | AM27: =IF($B27="","",AJ27/AI27) | AN27: =IF($B27="",-1,AM27-ROW()/100000) -> -1
C28: =FALSE() -> FALSE | D28: =FALSE() -> FALSE | E28: =FALSE() -> FALSE | F28: =FALSE() -> FALSE | G28: =FALSE() -> FALSE | H28: =FALSE() -> FALSE | I28: =FALSE() -> FALSE | J28: =FALSE() -> FALSE | ... AG28: =FALSE() -> FALSE | AI28: =IF($B28="","",$AP$3) | AJ28: =IF($B28="","",COUNTIF(C28:AG28,TRUE())) | AK28: =IF($B28="","",AI28-AJ28) | AL28: =IF($B28="","",AJ28/AI28) | AM28: =IF($B28="","",AJ28/AI28) | AN28: =IF($B28="",-1,AM28-ROW()/100000) -> -1
B29: Daily % | C29: =IF(OR(C$16="",SUMPRODUCT(--(LEN($B$17:$B$28)>0))=0),"",SUMPRODUCT(($B$17:$B$28<>"")*(C$17:C$28=TRUE()))/SUMPRODUCT(--(LEN($B$17:$B$28)>0))) -> 0 | D29: =IF(OR(D$16="",SUMPRODUCT(--(LEN($B$17:$B$28)>0))=0),"",SUMPRODUCT(($B$17:$B$28<>"")*(D$17:D$28=TRUE()))/SUMPRODUCT(--(LEN($B$17:$B$28)>0))) -> 0 | E29: =IF(OR(E$16="",SUMPRODUCT(--(LEN($B$17:$B$28)>0))=0),"",SUMPRODUCT(($B$17:$B$28<>"")*(E$17:E$28=TRUE()))/SUMPRODUCT(--(LEN($B$17:$B$28)>0))) -> 0 | F29: =IF(OR(F$16="",SUMPRODUCT(--(LEN($B$17:$B$28)>0))=0),"",SUMPRODUCT(($B$17:$B$28<>"")*(F$17:F$28=TRUE()))/SUMPRODUCT(--(LEN($B$17:$B$28)>0))) -> 0 | G29: =IF(OR(G$16="",SUMPRODUCT(--(LEN($B$17:$B$28)>0))=0),"",SUMPRODUCT(($B$17:$B$28<>"")*(G$17:G$28=TRUE()))/SUMPRODUCT(--(LEN($B$17:$B$28)>0))) -> 0 | H29: =IF(OR(H$16="",SUMPRODUCT(--(LEN($B$17:$B$28)>0))=0),"",SUMPRODUCT(($B$17:$B$28<>"")*(H$17:H$28=TRUE()))/SUMPRODUCT(--(LEN($B$17:$B$28)>0))) -> 0 | I29: =IF(OR(I$16="",SUMPRODUCT(--(LEN($B$17:$B$28)>0))=0),"",SUMPRODUCT(($B$17:$B$28<>"")*(I$17:I$28=TRUE()))/SUMPRODUCT(--(LEN($B$17:$B$28)>0))) -> 0 | J29: =IF(OR(J$16="",SUMPRODUCT(--(LEN($B$17:$B$28)>0))=0),"",SUMPRODUCT(($B$17:$B$28<>"")*(J$17:J$28=TRUE()))/SUMPRODUCT(--(LEN($B$17:$B$28)>0))) -> 0 | ... AG29: =IF(OR(AG$16="",SUMPRODUCT(--(LEN($B$17:$B$28)>0))=0),"",SUMPRODUCT(($B$17:$B$28<>"")*(AG$17:AG$28=TRUE()))/SUMPRODUCT(--(LEN($B$17:$B$28)>0))) -> 0
C31: Overall Wellness | AI31: TOP 10 HABITS
B32: Mood (1-10) | AI32: 1 | AJ32: =IF(LARGE($AN$17:$AN$28,1)<0,"",INDEX($B$17:$B$28,MATCH(LARGE($AN$17:$AN$28,1),$AN$17:$AN$28,0))) | AM32: =IF(AJ32="","",INDEX($AM$17:$AM$28,MATCH(LARGE($AN$17:$AN$28,1),$AN$17:$AN$28,0)))
B33: Hours of Sleep | AI33: 2 | AJ33: =IF(LARGE($AN$17:$AN$28,2)<0,"",INDEX($B$17:$B$28,MATCH(LARGE($AN$17:$AN$28,2),$AN$17:$AN$28,0))) | AM33: =IF(AJ33="","",INDEX($AM$17:$AM$28,MATCH(LARGE($AN$17:$AN$28,2),$AN$17:$AN$28,0)))
AI34: 3 | AJ34: =IF(LARGE($AN$17:$AN$28,3)<0,"",INDEX($B$17:$B$28,MATCH(LARGE($AN$17:$AN$28,3),$AN$17:$AN$28,0))) | AM34: =IF(AJ34="","",INDEX($AM$17:$AM$28,MATCH(LARGE($AN$17:$AN$28,3),$AN$17:$AN$28,0)))
AI35: 4 | AJ35: =IF(LARGE($AN$17:$AN$28,4)<0,"",INDEX($B$17:$B$28,MATCH(LARGE($AN$17:$AN$28,4),$AN$17:$AN$28,0))) | AM35: =IF(AJ35="","",INDEX($AM$17:$AM$28,MATCH(LARGE($AN$17:$AN$28,4),$AN$17:$AN$28,0)))
AI36: 5 | AJ36: =IF(LARGE($AN$17:$AN$28,5)<0,"",INDEX($B$17:$B$28,MATCH(LARGE($AN$17:$AN$28,5),$AN$17:$AN$28,0))) | AM36: =IF(AJ36="","",INDEX($AM$17:$AM$28,MATCH(LARGE($AN$17:$AN$28,5),$AN$17:$AN$28,0)))
AI37: 6 | AJ37: =IF(LARGE($AN$17:$AN$28,6)<0,"",INDEX($B$17:$B$28,MATCH(LARGE($AN$17:$AN$28,6),$AN$17:$AN$28,0))) | AM37: =IF(AJ37="","",INDEX($AM$17:$AM$28,MATCH(LARGE($AN$17:$AN$28,6),$AN$17:$AN$28,0)))
AI38: 7 | AJ38: =IF(LARGE($AN$17:$AN$28,7)<0,"",INDEX($B$17:$B$28,MATCH(LARGE($AN$17:$AN$28,7),$AN$17:$AN$28,0))) | AM38: =IF(AJ38="","",INDEX($AM$17:$AM$28,MATCH(LARGE($AN$17:$AN$28,7),$AN$17:$AN$28,0)))
AI39: 8 | AJ39: =IF(LARGE($AN$17:$AN$28,8)<0,"",INDEX($B$17:$B$28,MATCH(LARGE($AN$17:$AN$28,8),$AN$17:$AN$28,0))) | AM39: =IF(AJ39="","",INDEX($AM$17:$AM$28,MATCH(LARGE($AN$17:$AN$28,8),$AN$17:$AN$28,0)))
AI40: 9 | AJ40: =IF(LARGE($AN$17:$AN$28,9)<0,"",INDEX($B$17:$B$28,MATCH(LARGE($AN$17:$AN$28,9),$AN$17:$AN$28,0))) | AM40: =IF(AJ40="","",INDEX($AM$17:$AM$28,MATCH(LARGE($AN$17:$AN$28,9),$AN$17:$AN$28,0)))
AI41: 10 | AJ41: =IF(LARGE($AN$17:$AN$28,10)<0,"",INDEX($B$17:$B$28,MATCH(LARGE($AN$17:$AN$28,10),$AN$17:$AN$28,0))) | AM41: =IF(AJ41="","",INDEX($AM$17:$AM$28,MATCH(LARGE($AN$17:$AN$28,10),$AN$17:$AN$28,0)))
C48: =IF(C$16="","",C$15) -> Su | D48: =IF(D$16="","",D$15) -> Mo | E48: =IF(E$16="","",E$15) -> Tu | F48: =IF(F$16="","",F$15) -> We | G48: =IF(G$16="","",G$15) -> Th | H48: =IF(H$16="","",H$15) -> Fr | I48: =IF(I$16="","",I$15) -> Sa | J48: =IF(J$16="","",J$15) -> Su | ... AG48: =IF(AG$16="","",AG$15) -> Tu

Sheet April
AQ1: January
B2: HABIT TRACKER | C2: Daily Progress | AA2: Weekly Progress | AI2: Goal | AK2: Overall Stats | AO2: MonthNo | AP2: =MATCH($B$9,$AQ$1:$AQ$12,0) -> 4 | AQ2: February
AI3: =SUMPRODUCT(--(LEN($B$17:$B$28)>0))*$AP$3 -> 300 | AK3: =IF(AI3=0,0,AI6/AI3) -> 0 | AO3: Days | AP3: =DAY(DATE($B$7,$AP$2+1,0)) -> 30 | AQ3: March
AQ4: April
B5: SETTINGS | AI5: Completed | AO5: Completed | AP5: =AI6 -> 0 | AQ5: May
B6: Year | AI6: =SUMPRODUCT(($B$17:$B$28<>"")*($C$17:$AG$28=TRUE())) -> 0 | AO6: Left | AP6: =AI9 -> 300 | AQ6: June
B7: =January!$B$7 -> 2026 | AQ7: July
B8: Month | AI8: Left | AO8: Week 1 | AP8: =IF(OR(COUNTIF(C$16:I$16,">0")=0,SUMPRODUCT(--(LEN($B$17:$B$28)>0))=0),0,SUMPRODUCT(($B$17:$B$28<>"")*(C$17:I$28=TRUE()))/(SUMPRODUCT(--(LEN($B$17:$B$28)>0))*COUNTIF(C$16:I$16,">0"))) -> 0 | AQ8: August
B9: April | AI9: =AI3-AI6 -> 300 | AO9: Week 2 | AP9: =IF(OR(COUNTIF(J$16:P$16,">0")=0,SUMPRODUCT(--(LEN($B$17:$B$28)>0))=0),0,SUMPRODUCT(($B$17:$B$28<>"")*(J$17:P$28=TRUE()))/(SUMPRODUCT(--(LEN($B$17:$B$28)>0))*COUNTIF(J$16:P$16,">0"))) -> 0 | AQ9: September
B10: How to use: tick the boxes each day; pick Mood (1-10) and Sleep (hrs) below the grid; rename habits in column B. Blue text = editable. | AO10: Week 3 | AP10: =IF(OR(COUNTIF(Q$16:W$16,">0")=0,SUMPRODUCT(--(LEN($B$17:$B$28)>0))=0),0,SUMPRODUCT(($B$17:$B$28<>"")*(Q$17:W$28=TRUE()))/(SUMPRODUCT(--(LEN($B$17:$B$28)>0))*COUNTIF(Q$16:W$16,">0"))) -> 0 | AQ10: October
AO11: Week 4 | AP11: =IF(OR(COUNTIF(X$16:AD$16,">0")=0,SUMPRODUCT(--(LEN($B$17:$B$28)>0))=0),0,SUMPRODUCT(($B$17:$B$28<>"")*(X$17:AD$28=TRUE()))/(SUMPRODUCT(--(LEN($B$17:$B$28)>0))*COUNTIF(X$16:AD$16,">0"))) -> 0 | AQ11: November
AO12: Week 5 | AP12: =IF(OR(COUNTIF(AE$16:AG$16,">0")=0,SUMPRODUCT(--(LEN($B$17:$B$28)>0))=0),0,SUMPRODUCT(($B$17:$B$28<>"")*(AE$17:AG$28=TRUE()))/(SUMPRODUCT(--(LEN($B$17:$B$28)>0))*COUNTIF(AE$16:AG$16,">0"))) -> 0 | AQ12: December
B14: My Habits | C14: Week 1 | J14: Week 2 | Q14: Week 3 | X14: Week 4 | AE14: Week 5 | AI14: Analysis
C15: =IF(1>$AP$3,"",CHOOSE(WEEKDAY(DATE($B$7,$AP$2,1)),"Su","Mo","Tu","We","Th","Fr","Sa")) -> We | D15: =IF(2>$AP$3,"",CHOOSE(WEEKDAY(DATE($B$7,$AP$2,2)),"Su","Mo","Tu","We","Th","Fr","Sa")) -> Th | E15: =IF(3>$AP$3,"",CHOOSE(WEEKDAY(DATE($B$7,$AP$2,3)),"Su","Mo","Tu","We","Th","Fr","Sa")) -> Fr | F15: =IF(4>$AP$3,"",CHOOSE(WEEKDAY(DATE($B$7,$AP$2,4)),"Su","Mo","Tu","We","Th","Fr","Sa")) -> Sa | G15: =IF(5>$AP$3,"",CHOOSE(WEEKDAY(DATE($B$7,$AP$2,5)),"Su","Mo","Tu","We","Th","Fr","Sa")) -> Su | H15: =IF(6>$AP$3,"",CHOOSE(WEEKDAY(DATE($B$7,$AP$2,6)),"Su","Mo","Tu","We","Th","Fr","Sa")) -> Mo | I15: =IF(7>$AP$3,"",CHOOSE(WEEKDAY(DATE($B$7,$AP$2,7)),"Su","Mo","Tu","We","Th","Fr","Sa")) -> Tu | J15: =IF(8>$AP$3,"",CHOOSE(WEEKDAY(DATE($B$7,$AP$2,8)),"Su","Mo","Tu","We","Th","Fr","Sa")) -> We | K15: =IF(9>$AP$3,"",CHOOSE(WEEKDAY(DATE($B$7,$AP$2,9)),"Su","Mo","Tu","We","Th","Fr","Sa")) -> Th | L15: =IF(10>$AP$3,"",CHOOSE(WEEKDAY(DATE($B$7,$AP$2,10)),"Su","Mo","Tu","We","Th","Fr","Sa")) -> Fr | M15: =IF(11>$AP$3,"",CHOOSE(WEEKDAY(DATE($B$7,$AP$2,11)),"Su","Mo","Tu","We","Th","Fr","Sa")) -> Sa | N15: =IF(12>$AP$3,"",CHOOSE(WEEKDAY(DATE($B$7,$AP$2,12)),"Su","Mo","Tu","We","Th","Fr","Sa")) -> Su | O15: =IF(13>$AP$3,"",CHOOSE(WEEKDAY(DATE($B$7,$AP$2,13)),"Su","Mo","Tu","We","Th","Fr","Sa")) -> Mo | P15: =IF(14>$AP$3,"",CHOOSE(WEEKDAY(DATE($B$7,$AP$2,14)),"Su","Mo","Tu","We","Th","Fr","Sa")) -> Tu | Q15: =IF(15>$AP$3,"",CHOOSE(WEEKDAY(DATE($B$7,$AP$2,15)),"Su","Mo","Tu","We","Th","Fr","Sa")) -> We | R15: =IF(16>$AP$3,"",CHOOSE(WEEKDAY(DATE($B$7,$AP$2,16)),"Su","Mo","Tu","We","Th","Fr","Sa")) -> Th | S15: =IF(17>$AP$3,"",CHOOSE(WEEKDAY(DATE($B$7,$AP$2,17)),"Su","Mo","Tu","We","Th","Fr","Sa")) -> Fr | T15: =IF(18>$AP$3,"",CHOOSE(WEEKDAY(DATE($B$7,$AP$2,18)),"Su","Mo","Tu","We","Th","Fr","Sa")) -> Sa | U15: =IF(19>$AP$3,"",CHOOSE(WEEKDAY(DATE($B$7,$AP$2,19)),"Su","Mo","Tu","We","Th","Fr","Sa")) -> Su | V15: =IF(20>$AP$3,"",CHOOSE(WEEKDAY(DATE($B$7,$AP$2,20)),"Su","Mo","Tu","We","Th","Fr","Sa")) -> Mo | W15: =IF(21>$AP$3,"",CHOOSE(WEEKDAY(DATE($B$7,$AP$2,21)),"Su","Mo","Tu","We","Th","Fr","Sa")) -> Tu | X15: =IF(22>$AP$3,"",CHOOSE(WEEKDAY(DATE($B$7,$AP$2,22)),"Su","Mo","Tu","We","Th","Fr","Sa")) -> We | Y15: =IF(23>$AP$3,"",CHOOSE(WEEKDAY(DATE($B$7,$AP$2,23)),"Su","Mo","Tu","We","Th","Fr","Sa")) -> Th | Z15: =IF(24>$AP$3,"",CHOOSE(WEEKDAY(DATE($B$7,$AP$2,24)),"Su","Mo","Tu","We","Th","Fr","Sa")) -> Fr | AA15: =IF(25>$AP$3,"",CHOOSE(WEEKDAY(DATE($B$7,$AP$2,25)),"Su","Mo","Tu","We","Th","Fr","Sa")) -> Sa | AB15: =IF(26>$AP$3,"",CHOOSE(WEEKDAY(DATE($B$7,$AP$2,26)),"Su","Mo","Tu","We","Th","Fr","Sa")) -> Su | AC15: =IF(27>$AP$3,"",CHOOSE(WEEKDAY(DATE($B$7,$AP$2,27)),"Su","Mo","Tu","We","Th","Fr","Sa")) -> Mo | AD15: =IF(28>$AP$3,"",CHOOSE(WEEKDAY(DATE($B$7,$AP$2,28)),"Su","Mo","Tu","We","Th","Fr","Sa")) -> Tu | AE15: =IF(29>$AP$3,"",CHOOSE(WEEKDAY(DATE($B$7,$AP$2,29)),"Su","Mo","Tu","We","Th","Fr","Sa")) -> We | AF15: =IF(30>$AP$3,"",CHOOSE(WEEKDAY(DATE($B$7,$AP$2,30)),"Su","Mo","Tu","We","Th","Fr","Sa")) -> Th | AG15: =IF(31>$AP$3,"",CHOOSE(WEEKDAY(DATE($B$7,$AP$2,31)),"Su","Mo","Tu","We","Th","Fr","Sa"))
C16: =IF(1>$AP$3,"",1) -> 1 | D16: =IF(2>$AP$3,"",2) -> 2 | E16: =IF(3>$AP$3,"",3) -> 3 | F16: =IF(4>$AP$3,"",4) -> 4 | G16: =IF(5>$AP$3,"",5) -> 5 | H16: =IF(6>$AP$3,"",6) -> 6 | I16: =IF(7>$AP$3,"",7) -> 7 | J16: =IF(8>$AP$3,"",8) -> 8 | K16: =IF(9>$AP$3,"",9) -> 9 | L16: =IF(10>$AP$3,"",10) -> 10 | M16: =IF(11>$AP$3,"",11) -> 11 | N16: =IF(12>$AP$3,"",12) -> 12 | O16: =IF(13>$AP$3,"",13) -> 13 | P16: =IF(14>$AP$3,"",14) -> 14 | Q16: =IF(15>$AP$3,"",15) -> 15 | R16: =IF(16>$AP$3,"",16) -> 16 | S16: =IF(17>$AP$3,"",17) -> 17 | T16: =IF(18>$AP$3,"",18) -> 18 | U16: =IF(19>$AP$3,"",19) -> 19 | V16: =IF(20>$AP$3,"",20) -> 20 | W16: =IF(21>$AP$3,"",21) -> 21 | X16: =IF(22>$AP$3,"",22) -> 22 | Y16: =IF(23>$AP$3,"",23) -> 23 | Z16: =IF(24>$AP$3,"",24) -> 24 | AA16: =IF(25>$AP$3,"",25) -> 25 | AB16: =IF(26>$AP$3,"",26) -> 26 | AC16: =IF(27>$AP$3,"",27) -> 27 | AD16: =IF(28>$AP$3,"",28) -> 28 | AE16: =IF(29>$AP$3,"",29) -> 29 | AF16: =IF(30>$AP$3,"",30) -> 30 | AG16: =IF(31>$AP$3,"",31) | AI16: Goal | AJ16: Actual | AK16: Left | AL16: Progress | AM16: %
B17: Wake up at 05:00 ⏰ | C17: =FALSE() -> FALSE | D17: =FALSE() -> FALSE | E17: =FALSE() -> FALSE | F17: =FALSE() -> FALSE | G17: =FALSE() -> FALSE | H17: =FALSE() -> FALSE | I17: =FALSE() -> FALSE | J17: =FALSE() -> FALSE | ... AG17: =FALSE() -> FALSE | AI17: =IF($B17="","",$AP$3) -> 30 | AJ17: =IF($B17="","",COUNTIF(C17:AG17,TRUE())) -> 0 | AK17: =IF($B17="","",AI17-AJ17) -> 30 | AL17: =IF($B17="","",AJ17/AI17) -> 0 | AM17: =IF($B17="","",AJ17/AI17) -> 0 | AN17: =IF($B17="",-1,AM17-ROW()/100000) -> -0.00017
B18: Stretching 🧘 | C18: =FALSE() -> FALSE | D18: =FALSE() -> FALSE | E18: =FALSE() -> FALSE | F18: =FALSE() -> FALSE | G18: =FALSE() -> FALSE | H18: =FALSE() -> FALSE | I18: =FALSE() -> FALSE | J18: =FALSE() -> FALSE | ... AG18: =FALSE() -> FALSE | AI18: =IF($B18="","",$AP$3) -> 30 | AJ18: =IF($B18="","",COUNTIF(C18:AG18,TRUE())) -> 0 | AK18: =IF($B18="","",AI18-AJ18) -> 30 | AL18: =IF($B18="","",AJ18/AI18) -> 0 | AM18: =IF($B18="","",AJ18/AI18) -> 0 | AN18: =IF($B18="",-1,AM18-ROW()/100000) -> -0.00018
B19: Gym 💪 | C19: =FALSE() -> FALSE | D19: =FALSE() -> FALSE | E19: =FALSE() -> FALSE | F19: =FALSE() -> FALSE | G19: =FALSE() -> FALSE | H19: =FALSE() -> FALSE | I19: =FALSE() -> FALSE | J19: =FALSE() -> FALSE | ... AG19: =FALSE() -> FALSE | AI19: =IF($B19="","",$AP$3) -> 30 | AJ19: =IF($B19="","",COUNTIF(C19:AG19,TRUE())) -> 0 | AK19: =IF($B19="","",AI19-AJ19) -> 30 | AL19: =IF($B19="","",AJ19/AI19) -> 0 | AM19: =IF($B19="","",AJ19/AI19) -> 0 | AN19: =IF($B19="",-1,AM19-ROW()/100000) -> -0.00019
B20: Reading / Learning 📖 | C20: =FALSE() -> FALSE | D20: =FALSE() -> FALSE | E20: =FALSE() -> FALSE | F20: =FALSE() -> FALSE | G20: =FALSE() -> FALSE | H20: =FALSE() -> FALSE | I20: =FALSE() -> FALSE | J20: =FALSE() -> FALSE | ... AG20: =FALSE() -> FALSE | AI20: =IF($B20="","",$AP$3) -> 30 | AJ20: =IF($B20="","",COUNTIF(C20:AG20,TRUE())) -> 0 | AK20: =IF($B20="","",AI20-AJ20) -> 30 | AL20: =IF($B20="","",AJ20/AI20) -> 0 | AM20: =IF($B20="","",AJ20/AI20) -> 0 | AN20: =IF($B20="",-1,AM20-ROW()/100000) -> -0.0002
B21: Day Planning 📅 | C21: =FALSE() -> FALSE | D21: =FALSE() -> FALSE | E21: =FALSE() -> FALSE | F21: =FALSE() -> FALSE | G21: =FALSE() -> FALSE | H21: =FALSE() -> FALSE | I21: =FALSE() -> FALSE | J21: =FALSE() -> FALSE | ... AG21: =FALSE() -> FALSE | AI21: =IF($B21="","",$AP$3) -> 30 | AJ21: =IF($B21="","",COUNTIF(C21:AG21,TRUE())) -> 0 | AK21: =IF($B21="","",AI21-AJ21) -> 30 | AL21: =IF($B21="","",AJ21/AI21) -> 0 | AM21: =IF($B21="","",AJ21/AI21) -> 0 | AN21: =IF($B21="",-1,AM21-ROW()/100000) -> -0.00021
B22: Project Work 🎯 | C22: =FALSE() -> FALSE | D22: =FALSE() -> FALSE | E22: =FALSE() -> FALSE | F22: =FALSE() -> FALSE | G22: =FALSE() -> FALSE | H22: =FALSE() -> FALSE | I22: =FALSE() -> FALSE | J22: =FALSE() -> FALSE | ... AG22: =FALSE() -> FALSE | AI22: =IF($B22="","",$AP$3) -> 30 | AJ22: =IF($B22="","",COUNTIF(C22:AG22,TRUE())) -> 0 | AK22: =IF($B22="","",AI22-AJ22) -> 30 | AL22: =IF($B22="","",AJ22/AI22) -> 0 | AM22: =IF($B22="","",AJ22/AI22) -> 0 | AN22: =IF($B22="",-1,AM22-ROW()/100000) -> -0.00022
B23: No Alcohol 🚫 | C23: =FALSE() -> FALSE | D23: =FALSE() -> FALSE | E23: =FALSE() -> FALSE | F23: =FALSE() -> FALSE | G23: =FALSE() -> FALSE | H23: =FALSE() -> FALSE | I23: =FALSE() -> FALSE | J23: =FALSE() -> FALSE | ... AG23: =FALSE() -> FALSE | AI23: =IF($B23="","",$AP$3) -> 30 | AJ23: =IF($B23="","",COUNTIF(C23:AG23,TRUE())) -> 0 | AK23: =IF($B23="","",AI23-AJ23) -> 30 | AL23: =IF($B23="","",AJ23/AI23) -> 0 | AM23: =IF($B23="","",AJ23/AI23) -> 0 | AN23: =IF($B23="",-1,AM23-ROW()/100000) -> -0.00023
B24: Social Media Detox 🌿 | C24: =FALSE() -> FALSE | D24: =FALSE() -> FALSE | E24: =FALSE() -> FALSE | F24: =FALSE() -> FALSE | G24: =FALSE() -> FALSE | H24: =FALSE() -> FALSE | I24: =FALSE() -> FALSE | J24: =FALSE() -> FALSE | ... AG24: =FALSE() -> FALSE | AI24: =IF($B24="","",$AP$3) -> 30 | AJ24: =IF($B24="","",COUNTIF(C24:AG24,TRUE())) -> 0 | AK24: =IF($B24="","",AI24-AJ24) -> 30 | AL24: =IF($B24="","",AJ24/AI24) -> 0 | AM24: =IF($B24="","",AJ24/AI24) -> 0 | AN24: =IF($B24="",-1,AM24-ROW()/100000) -> -0.00024
B25: Goal Journaling 📒 | C25: =FALSE() -> FALSE | D25: =FALSE() -> FALSE | E25: =FALSE() -> FALSE | F25: =FALSE() -> FALSE | G25: =FALSE() -> FALSE | H25: =FALSE() -> FALSE | I25: =FALSE() -> FALSE | J25: =FALSE() -> FALSE | ... AG25: =FALSE() -> FALSE | AI25: =IF($B25="","",$AP$3) -> 30 | AJ25: =IF($B25="","",COUNTIF(C25:AG25,TRUE())) -> 0 | AK25: =IF($B25="","",AI25-AJ25) -> 30 | AL25: =IF($B25="","",AJ25/AI25) -> 0 | AM25: =IF($B25="","",AJ25/AI25) -> 0 | AN25: =IF($B25="",-1,AM25-ROW()/100000) -> -0.00025
B26: Cold Shower 🚿 | C26: =FALSE() -> FALSE | D26: =FALSE() -> FALSE | E26: =FALSE() -> FALSE | F26: =FALSE() -> FALSE | G26: =FALSE() -> FALSE | H26: =FALSE() -> FALSE | I26: =FALSE() -> FALSE | J26: =FALSE() -> FALSE | ... AG26: =FALSE() -> FALSE | AI26: =IF($B26="","",$AP$3) -> 30 | AJ26: =IF($B26="","",COUNTIF(C26:AG26,TRUE())) -> 0 | AK26: =IF($B26="","",AI26-AJ26) -> 30 | AL26: =IF($B26="","",AJ26/AI26) -> 0 | AM26: =IF($B26="","",AJ26/AI26) -> 0 | AN26: =IF($B26="",-1,AM26-ROW()/100000) -> -0.00026
